Workbook

Sheet Totals
C3: Canadian Nuclear Outlook
B4: Year | C4: Total Per Year | D4: A&R Resources | E4: IRP/RFP Resources | F4: Uprates Capacity
B5: 2026 & Operating | C5: =SUM(D5:F5) -> 13049 | D5: =SUM('A&R Pivot'!B4:B13) -> 13049 | E5: 0 | F5: 0
B6: 2027 | C6: =SUM(D6:F6) -> 0 | D6: 0 | E6: 0 | F6: 0
B7: 2028 | C7: =SUM(D7:F7) -> 5 | D7: =GETPIVOTDATA("Unit Nameplate Capacity",'A&R Pivot'!$A$3,"Years (Scenario In Service Date)",2028) -> 5 | E7: 0 | F7: 0
B8: 2029 | C8: =SUM(D8:F8) -> 0 | D8: 0 | E8: 0 | F8: 0
B9: 2030 | C9: =SUM(D9:F9) -> 1125 | D9: =GETPIVOTDATA("Unit Nameplate Capacity",'A&R Pivot'!$A$3,"Years (Scenario In Service Date)",2030) -> 600 | E9: 0 | F9: =GETPIVOTDATA("Winter Value",'Uprates Pivot'!$A$3,"Years (Upgrade Date)",2030) -> 525
B10: 2031 | C10: =SUM(D10:F10) -> 0 | D10: 0 | E10: 0 | F10: 0
B11: 2032 | C11: =SUM(D11:F11) -> 0 | D11: 0 | E11: 0 | F11: 0
B12: 2033 | C12: =SUM(D12:F12) -> 315 | D12: =GETPIVOTDATA("Unit Nameplate Capacity",'A&R Pivot'!$A$3,"Years (Scenario In Service Date)",2033) -> 315 | E12: 0 | F12: 0
B13: 2034 | C13: =SUM(D13:F13) -> 0 | D13: 0 | E13: 0 | F13: 0
B14: 2035 | C14: =SUM(D14:F14) -> 3100 | D14: =GETPIVOTDATA("Unit Nameplate Capacity",'A&R Pivot'!$A$3,"Years (Scenario In Service Date)",2035) -> 3100 | E14: 0 | F14: 0
B15: 2035 Outlook | C15: =SUM(C5:C14) -> 17594
B16: 2036 | C16: =SUM(D16:F16) -> 300 | D16: =GETPIVOTDATA("Unit Nameplate Capacity",'A&R Pivot'!$A$3,"Years (Scenario In Service Date)",2036) -> 300 | E16: 0 | F16: 0
B17: 2037 | C17: =SUM(D17:F17) -> 300 | D17: 0 | E17: =GETPIVOTDATA("Current Operating Capacity",'IRP & RFP Pivot'!$A$3,"Year",2037) -> 300 | F17: 0
B18: 2038 | C18: =SUM(D18:F18) -> 2900 | D18: =GETPIVOTDATA("Unit Nameplate Capacity",'A&R Pivot'!$A$3,"Years (Scenario In Service Date)",2038) -> 2300 | E18: =GETPIVOTDATA("Current Operating Capacity",'IRP & RFP Pivot'!$A$3,"Year",2038) -> 600 | F18: 0
B19: 2039 | C19: =SUM(D19:F19) -> 1800 | D19: =GETPIVOTDATA("Unit Nameplate Capacity",'A&R Pivot'!$A$3,"Years (Scenario In Service Date)",2039) -> 1200 | E19: =GETPIVOTDATA("Current Operating Capacity",'IRP & RFP Pivot'!$A$3,"Year",2039) -> 600 | F19: 0
B20: 2040 | C20: =SUM(D20:F20) -> 4840 | D20: =GETPIVOTDATA("Unit Nameplate Capacity",'A&R Pivot'!$A$3,"Years (Scenario In Service Date)",2040) -> 3240 | E20: =GETPIVOTDATA("Current Operating Capacity",'IRP & RFP Pivot'!$A$3,"Year",2040) -> 1600 | F20: 0
B21: 2040 Outlook | C21: =SUM(C15:C20) -> 27734

Sheet A&R
A1: Power Plant Unit Key | B1: Power Plant Key | C1: AUR RNA ID | D1: Aurora Area | E1: ISO Project ID | F1: SNL Unit Name | G1: Interconnected Utility Company | H1: Power Control Area | I1: Fuel Type | J1: County | K1: State | L1: Dispatching ISO | M1: Unit Nameplate Capacity | N1: Scenario Operating Status | O1: Operating Status Comments | P1: Scenario In Service Date | Q1: In Service Date Source | R1: In Service Date Comments | S1: SNL Operating Status | T1: SNL In Service Date | U1: Turbine Type | V1: Turbine Manufacturer | W1: Manufacturer | X1: Technology Type | Y1: Generation Technology | Z1: Technology Detail | AA1: Include In Scenario Comments | AB1: Retirement Date Comments | AC1: Longitude | AD1: Latitude
A2: 27151 | B2: 11561 | C2: NR_SNL27151 | D2: 36 | F2: Nanticoke CDU 2 | H2: Independent Electricity System Operator | I2: Nuclear | J2: Haldimand | K2: ON | L2: Ontario | M2: 1350 | N2: Announced | O2: Per New Units File and OPG Energy Plan | P2: 52018 | Q2: Sales | R2: Per New Units File provided by Robert - 8.12.2025 | S2: Terminated | X2: Nuclear | Y2: Nuclear | Z2: CANDU | AA2: Per New Units File | AC2: -80.03778 | AD2: 42.81159
A3: 26429 | B3: 11561 | C3: NR_SNL26429 | D3: 36 | F3: Nanticoke CDU 1 | H3: Independent Electricity System Operator | I3: Nuclear | J3: Haldimand | K3: ON | L3: Ontario | M3: 1350 | N3: Announced | O3: Per New Units File and OPG Energy Plan | P3: 51653 | Q3: Sales | R3: Per New Units File provided by Robert - 8.12.2025 | S3: Terminated | X3: Nuclear | Y3: Nuclear | Z3: CANDU | AA3: Per New Units File | AC3: -80.03778 | AD3: 42.81159
A4: 27305 | B4: 12447 | C4: NR_SNL27305 | D4: 8 | F4: Bruce CDU 4 | H4: Independent Electricity System Operator | I4: Nuclear | J4: Kincardine | K4: ON | L4: Ontario | M4: 1200 | N4: Early Development | P4: 51653 | Q4: State/Local Document | R4: Per OPGs Energy Plan - 8.12.2025 | S4: Early Development | T4: 51653 | X4: Nuclear | Y4: Nuclear | Z4: CANDU | AA4: Units called out in OPGs plan for new large scale nuclear | AC4: -81.57504 | AD4: 44.34026
A5: 27304 | B5: 12447 | C5: NR_SNL27304 | D5: 8 | F5: Bruce CDU 3 | H5: Independent Electricity System Operator | I5: Nuclear | J5: Kincardine | K5: ON | L5: Ontario | M5: 1200 | N5: Early Development | P5: 51288 | Q5: State/Local Document | R5: Per OPGs Energy Plan - 8.12.2025 | S5: Early Development | T5: 51288 | X5: Nuclear | Y5: Nuclear | Z5: CANDU | AA5: Units called out in OPGs plan for new large scale nuclear | AC5: -81.57504 | AD5: 44.34026
A6: 27303 | B6: 12447 | C6: NR_SNL27303 | D6: 8 | F6: Bruce CDU 2 | H6: Independent Electricity System Operator | I6: Nuclear | J6: Kincardine | K6: ON | L6: Ontario | M6: 1200 | N6: Early Development | P6: 50922 | Q6: State/Local Document | R6: Per OPGs Energy Plan - 8.12.2025 | S6: Early Development | T6: 50922 | X6: Nuclear | Y6: Nuclear | Z6: CANDU | AA6: Units called out in OPGs plan for new large scale nuclear | AC6: -81.57504 | AD6: 44.34026
A7: 27302 | B7: 12447 | C7: NR_SNL27302 | D7: 8 | F7: Bruce CDU 1 | H7: Independent Electricity System Operator | I7: Nuclear | J7: Kincardine | K7: ON | L7: Ontario | M7: 1200 | N7: Early Development | P7: 50557 | Q7: State/Local Document | R7: Per OPGs Energy Plan - 8.12.2025 | S7: Early Development | T7: 50557 | X7: Nuclear | Y7: Nuclear | Z7: CANDU | AA7: Units called out in OPGs plan for new large scale nuclear | AC7: -81.57504 | AD7: 44.34026
A8: 244456 | B8: 129384 | C8: NR_SNL244456 | D8: 16 | F8: Wesleyville CDU 8 | H8: Independent Electricity System Operator | I8: Nuclear | J8: Port Hope | K8: ON | M8: 1100 | N8: Announced | P8: 54210 | Q8: SNL | R8: Monthly SNL Updates | S8: Announced | T8: 54210 | X8: Nuclear | Y8: Nuclear | Z8: CANDU | AA8: SNL New Unit | AC8: -78.39671 | AD8: 43.92245
A9: 243309 | B9: 132947 | C9: NR_SNL243309 | D9: 56 | F9: Peace River Nuclear CDU 2 | H9: Alberta Electric System Operator | I9: Nuclear | J9: Northern Lights County | K9: AB | M9: 1100 | N9: Early Development | P9: 49461 | S9: Early Development | T9: 49461 | X9: Nuclear | Y9: Nuclear | Z9: CANDU | AA9: SNL New Unit | AC9: -117.24906 | AD9: 56.45933
A10: 243310 | B10: 132947 | C10: NR_SNL243310 | D10: 56 | F10: Peace River Nuclear CDU 3 | H10: Alberta Electric System Operator | I10: Nuclear | J10: Northern Lights County | K10: AB | M10: 1100 | N10: Early Development | P10: 50557 | S10: Early Development | T10: 50557 | X10: Nuclear | Y10: Nuclear | Z10: CANDU | AA10: SNL New Unit | AC10: -117.24906 | AD10: 56.45933
A11: 243273 | B11: 132947 | C11: NR_SNL243273 | D11: 56 | F11: Peace River Nuclear CDU 1 | H11: Alberta Electric System Operator | I11: Nuclear | J11: Northern Lights County | K11: AB | M11: 1100 | N11: Early Development | P11: 49461 | Q11: SNL | R11: Monthly SNL Updates | S11: Early Development | T11: 49461 | X11: Nuclear | Y11: Nuclear | Z11: CANDU | AA11: SNL New Unit | AC11: -117.24906 | AD11: 56.45933
A12: 244455 | B12: 129384 | C12: NR_SNL244455 | D12: 16 | F12: Wesleyville CDU 7 | H12: Independent Electricity System Operator | I12: Nuclear | J12: Port Hope | K12: ON | M12: 1100 | N12: Announced | P12: 53479 | S12: Announced | T12: 53479 | X12: Nuclear | Y12: Nuclear | Z12: CANDU | AA12: SNL New Unit | AC12: -78.39671 | AD12: 43.92245
A13: 244442 | B13: 129384 | C13: NR_SNL244442 | D13: 16 | F13: Wesleyville CDU 5 | H13: Independent Electricity System Operator | I13: Nuclear | J13: Port Hope | K13: ON | M13: 1100 | N13: Announced | P13: 52749 | S13: Announced | T13: 52749 | X13: Nuclear | Y13: Nuclear | Z13: CANDU | AA13: SNL New Unit | AC13: -78.39671 | AD13: 43.92245
A14: 243311 | B14: 132947 | C14: NR_SNL243311 | D14: 56 | F14: Peace River Nuclear CDU 4 | H14: Alberta Electric System Operator | I14: Nuclear | J14: Northern Lights County | K14: AB | M14: 1100 | N14: Early Development | P14: 51288 | S14: Early Development | T14: 51288 | X14: Nuclear | Y14: Nuclear | Z14: CANDU | AA14: SNL New Unit | AC14: -117.24906 | AD14: 56.45933
A15: 244454 | B15: 129384 | C15: NR_SNL244454 | D15: 16 | F15: Wesleyville CDU 6 | H15: Independent Electricity System Operator | I15: Nuclear | J15: Port Hope | K15: ON | M15: 1100 | N15: Announced | P15: 53114 | S15: Announced | T15: 53114 | X15: Nuclear | Y15: Nuclear | Z15: CANDU | AA15: SNL New Unit | AC15: -78.39671 | AD15: 43.92245
A16: 239336 | B16: 129384 | C16: NR_SNL239336 | D16: 16 | F16: Wesleyville CDU 1 | H16: Independent Electricity System Operator | I16: Nuclear | J16: Port Hope | K16: ON | M16: 940 | N16: Announced | P16: 51288 | S16: Announced | T16: 51288 | X16: Nuclear | Y16: Nuclear | Z16: CANDU | AC16: -78.39671 | AD16: 43.92245
A17: 244440 | B17: 129384 | C17: NR_SNL244440 | D17: 16 | F17: Wesleyville CDU 3 | H17: Independent Electricity System Operator | I17: Nuclear | J17: Port Hope | K17: ON | M17: 940 | N17: Announced | P17: 52018 | S17: Announced | T17: 52018 | X17: Nuclear | Y17: Nuclear | Z17: CANDU | AA17: SNL New Unit | AC17: -78.39671 | AD17: 43.92245
A18: 244439 | B18: 129384 | C18: NR_SNL244439 | D18: 16 | F18: Wesleyville CDU 2 | H18: Independent Electricity System Operator | I18: Nuclear | J18: Port Hope | K18: ON | M18: 940 | N18: Announced | P18: 51653 | S18: Announced | T18: 51653 | X18: Nuclear | Y18: Nuclear | Z18: CANDU | AA18: SNL New Unit | AC18: -78.39671 | AD18: 43.92245
A19: 244441 | B19: 129384 | C19: NR_SNL244441 | D19: 16 | F19: Wesleyville CDU 4 | H19: Independent Electricity System Operator | I19: Nuclear | J19: Port Hope | K19: ON | M19: 940 | N19: Announced | P19: 52383 | S19: Announced | T19: 52383 | X19: Nuclear | Y19: Nuclear | Z19: CANDU | AA19: SNL New Unit | AC19: -78.39671 | AD19: 43.92245
A20: 18973 | B20: 2658 | C20: 1158 | D20: 36 | F20: Darlington CDU 2 | H20: Independent Electricity System Operator | I20: Nuclear | J20: Clarington | K20: ON | L20: Ontario | M20: 934 | N20: Operating | P20: 33147 | S20: Operating | T20: 33147 | W20: BBC | X20: Nuclear | Y20: Nuclear | Z20: CANDU | AB20: Based on Renewal Extension | AC20: -78.72455 | AD20: 43.86979
A21: 18972 | B21: 2658 | C21: 1157 | D21: 36 | F21: Darlington CDU 1 | H21: Independent Electricity System Operator | I21: Nuclear | J21: Clarington | K21: ON | L21: Ontario | M21: 934 | N21: Operating | O21: Monthly SNL Updates | P21: 33817 | S21: Operating | T21: 33909 | W21: ABB | X21: Nuclear | Y21: Nuclear | Z21: CANDU | AB21: Updated retirement date per request from S.S. 02262020 | AC21: -78.72455 | AD21: 43.86979
A22: 18974 | B22: 2658 | C22: 1159 | D22: 36 | F22: Darlington CDU 3 | H22: Independent Electricity System Operator | I22: Nuclear | J22: Clarington | K22: ON | L22: Ontario | M22: 934 | N22: Operating | P22: 33817 | S22: Operating | T22: 34001 | W22: BBC | X22: Nuclear | Y22: Nuclear | Z22: CANDU | AA22: Updating INCL_IN_SCN=Y to pass historical retirement date - 02032021 | AB22: Based on Renewal Extension | AC22: -78.72455 | AD22: 43.86979
A23: 18975 | B23: 2658 | C23: 1160 | D23: 36 | F23: Darlington CDU 4 | H23: Independent Electricity System Operator | I23: Nuclear | J23: Clarington | K23: ON | L23: Ontario | M23: 934 | N23: Operating | O23: Monthly SNL Updates | P23: 34134 | S23: Operating | T23: 34121 | W23: BBC | X23: Nuclear | Y23: Nuclear | Z23: CANDU | AB23: Updated retirement date per request from S.S. 02262020 | AC23: -78.72455 | AD23: 43.86979
A24: 28825 | B24: 1983 | C24: 560 | D24: 8 | F24: Bruce CDU 6 | H24: Independent Electricity System Operator | I24: Nuclear | J24: Kincardine | K24: ON | L24: Ontario | M24: 870 | N24: Operating | O24: Per SNL Article Bruce 6 has completed refurbishment of the unit on September 8th 2023 | P24: 30889 | S24: Operating | T24: 30926 | W24: GE | X24: Nuclear | Y24: Nuclear | Z24: CANDU | AA24: Updating INCL IN SCN = Y to bring in retired unit to pass retirement date to Aurora | AB24: Updating Retirement date per email from S.S. on 02252020 @ 1932 | AC24: -81.57504 | AD24: 44.34026
A25: 22335 | B25: 1983 | C25: 562 | D25: 8 | F25: Bruce CDU 8 | H25: Independent Electricity System Operator | I25: Nuclear | J25: Kincardine | K25: ON | L25: Ontario | M25: 840 | N25: Operating | P25: 30380 | S25: Operating | T25: 31898 | W25: GE | X25: Nuclear | Y25: Nuclear | Z25: CANDU | AB25: Updating Retirement date per email from S.S. on 02252020 @ 1932 | AC25: -81.57504 | AD25: 44.34026
A26: 28824 | B26: 1983 | C26: 559 | D26: 8 | F26: Bruce CDU 5 | H26: Independent Electricity System Operator | I26: Nuclear | J26: Kincardine | K26: ON | L26: Ontario | M26: 840 | N26: Operating | P26: 31107 | S26: Operating | T26: 31107 | X26: Nuclear | Y26: Nuclear | Z26: CANDU | AB26: Updating Retirement date per email from S.S. on 02252020 @ 1932 | AC26: -81.57504 | AD26: 44.34026
A27: 28826 | B27: 1983 | C27: 561 | D27: 8 | F27: Bruce CDU 7 | H27: Independent Electricity System Operator | I27: Nuclear | J27: Kincardine | K27: ON | L27: Ontario | M27: 840 | N27: Operating | P27: 31503 | S27: Operating | T27: 31503 | W27: Allis Chalmers | X27: Nuclear | Y27: Nuclear | Z27: CANDU | AB27: Updating Retirement date per email from S.S. on 02252020 @ 1932 | AC27: -81.57504 | AD27: 44.34026
A28: 28830 | B28: 1982 | C28: 558 | D28: 8 | F28: Bruce CDU 4 | H28: Independent Electricity System Operator | I28: Nuclear | J28: Kincardine | K28: ON | L28: Ontario | M28: 805 | N28: Out of Service | P28: 28873 | S28: Out of Service | T28: 28856 | W28: Parsons | X28: Nuclear | Y28: Nuclear | Z28: CANDU | AB28: Removing Accelerated Retirement Impact to Nuclear Units. | AC28: -81.57504 | AD28: 44.34026
A29: 22334 | B29: 1982 | C29: 555 | D29: 8 | F29: Bruce CDU 1 | H29: Independent Electricity System Operator | I29: Nuclear | J29: Kincardine | K29: ON | L29: Ontario | M29: 805 | N29: Operating | P29: 28369 | S29: Operating | T29: 28369 | W29: Parsons | X29: Nuclear | Y29: Nuclear | Z29: CANDU | AB29: Removing Accelerated Retirement Impact to Nuclear Units. | AC29: -81.57504 | AD29: 44.34026
A30: 28829 | B30: 1982 | C30: 556 | D30: 8 | F30: Bruce CDU 2 | H30: Independent Electricity System Operator | I30: Nuclear | J30: Kincardine | K30: ON | L30: Ontario | M30: 805 | N30: Operating | P30: 28369 | S30: Operating | T30: 28369 | W30: Parsons | X30: Nuclear | Y30: Nuclear | Z30: CANDU | AB30: Removing Accelerated Retirement Impact to Nuclear Units. | AC30: -81.57504 | AD30: 44.34026
A31: 28828 | B31: 1982 | C31: 557 | D31: 8 | F31: Bruce CDU 3 | H31: Independent Electricity System Operator | I31: Nuclear | J31: Kincardine | K31: ON | L31: Ontario | M31: 805 | N31: Out of Service | P31: 28525 | S31: Out of Service | T31: 28522 | W31: Parsons | X31: Nuclear | Y31: Nuclear | Z31: CANDU | AB31: Removing Accelerated Retirement Impact to Nuclear Units. | AC31: -81.57504 | AD31: 44.34026
A32: 22480 | B32: 5598 | C32: 3742 | D32: 27 | F32: Point Lepreau CDU 1 | H32: New Brunswick Power Corporation | I32: Nuclear | J32: Musquash | K32: NB | L32: New Brunswick | M32: 635 | N32: Operating | O32: Monthly SNL Updates | P32: 30348 | S32: Out of Service | T32: 30348 | W32: Parsons | X32: Nuclear | Y32: Nuclear | Z32: CANDU | AB32: Per Salesperson Feedback email on 05.05.21 at 08:16 | AC32: -66.45496 | AD32: 45.06929
A33: 39209 | B33: 5515 | C33: 3689 | D33: 35 | F33: Pickering CDU 8 | H33: Independent Electricity System Operator | I33: Nuclear | J33: Pickering | K33: ON | L33: Ontario | M33: 517 | N33: Operating | P33: 31444 | S33: Operating | T33: 31444 | W33: Parsons | X33: Nuclear | Y33: Nuclear | Z33: CANDU | AB33: The Units 5-8 will go through refurbishment in 2026-2032 and we expect an additional 30 years of service once complete - 2.1.2024 | AC33: -79.06381 | AD33: 43.80959
A34: 39207 | B34: 5515 | C34: 3687 | D34: 35 | F34: Pickering CDU 6 | H34: Independent Electricity System Operator | I34: Nuclear | J34: Pickering | K34: ON | L34: Ontario | M34: 517 | N34: Operating | P34: 30713 | S34: Operating | T34: 30713 | W34: Parsons | X34: Nuclear | Y34: Nuclear | Z34: CANDU | AB34: The Units 5-8 will go through refurbishment in 2026-2032 and we expect an additional 30 years of service once complete - 2.1.2024 | AC34: -79.06381 | AD34: 43.80959
A35: 39208 | B35: 5515 | C35: 3688 | D35: 35 | F35: Pickering CDU 7 | H35: Independent Electricity System Operator | I35: Nuclear | J35: Pickering | K35: ON | L35: Ontario | M35: 517 | N35: Operating | P35: 31048 | S35: Operating | T35: 31048 | W35: Parsons | X35: Nuclear | Y35: Nuclear | Z35: CANDU | AB35: The Units 5-8 will go through refurbishment in 2026-2032 and we expect an additional 30 years of service once complete - 2.1.2024 | AC35: -79.06381 | AD35: 43.80959
A36: 39206 | B36: 5515 | C36: 3686 | D36: 35 | F36: Pickering CDU 5 | H36: Independent Electricity System Operator | I36: Nuclear | J36: Pickering | K36: ON | L36: Ontario | M36: 517 | N36: Operating | P36: 30437 | S36: Operating | T36: 30437 | W36: Parsons | X36: Nuclear | Y36: Nuclear | Z36: CANDU | AB36: The Units 5-8 will go through refurbishment in 2026-2032 and we expect an additional 30 years of service once complete - 2.1.2024 | AC36: -79.06381 | AD36: 43.80959
A37: 227516 | B37: 120903 | C37: NR_SNL227516 | D37: 56 | F37: Saskatchewan SMR Nuclear CDU 1 | H37: SaskPower International Inc. | I37: Nuclear | M37: 315 | N37: Early Development | P37: 48731 | Q37: Correction | R37: Per Pradip Input - project is more likely for 2032 or beyond - 12.10.2025 | S37: Early Development | T37: 47635 | X37: Nuclear | Y37: Nuclear | Z37: CANDU
A38: 153909 | B38: 82278 | C38: NR_SNL153909 | F38: Point Lepreau OTH 1 | H38: New Brunswick Power Corporation | I38: Nuclear | J38: Musquash | K38: NB | L38: New Brunswick | M38: 300 | N38: Early Development | P38: 47484 | Q38: SNL | R38: Monthly SNL Updates | S38: Early Development | T38: 47484 | X38: Nuclear | Y38: Nuclear | AA38: Project is in New Units List - 4.30.2026 | AC38: -66.45488 | AD38: 45.06982
A39: 135176 | B39: 74030 | C39: NR_SNL135176 | D39: 36 | F39: Darlington BWR A | H39: Independent Electricity System Operator | I39: Nuclear | J39: Clarington | K39: ON | L39: Ontario | M39: 300 | N39: Under Construction | O39: Per Article Darlington SMR has been approved to start construction - 5.9.2025 | P39: 47635 | Q39: SNL | R39: Monthly SNL Updates | S39: Under Construction | T39: 47635 | X39: Nuclear | Y39: Nuclear | Z39: Boiling Water Reactor | AA39: Monthly SNL Updates | AC39: -78.72455 | AD39: 43.86979
A40: 221787 | B40: 74030 | C40: NR_SNL221787 | D40: 36 | F40: Darlington BWR D | H40: Independent Electricity System Operator | I40: Nuclear | J40: Clarington | K40: ON | L40: Ontario | M40: 300 | N40: Early Development | P40: 49461 | Q40: SNL | R40: Monthly SNL Updates | S40: Early Development | T40: 49461 | X40: Nuclear | Y40: Nuclear | Z40: Boiling Water Reactor | AC40: -78.72455 | AD40: 43.86979
...

Sheet IRP & RFP
A1: Unit Name | B1: Aur Rna Id | C1: Unit Key | D1: Unit Type | E1: Status | F1: Resources | G1: Year | H1: State/Province | I1: County/Parrish | J1: Area | K1: Primary Fuel Group | L1: Interconnected Utility Company | M1: Current Operating Capacity | N1: Scenario In Service Date | O1: Generation Technology | P1: Zip Code | Q1: Comments | R1: Created By | S1: Created User | T1: Created Date | U1: Updated By | V1: Updated User | W1: Updated Date
A2: Sask Power GE-Hitachi- 300 MW Nuclear | B2: NR_RFP7405 | C2: RFP7405 | D2: RFP | E2: Included | F2: 300 MW Nuclear | G2: 2037 | H2: Saskatchewan (SK) | J2: MRO_Saskatchewan~57 | K2: Nuclear | M2: 300 | N2: 50192 | O2: SMR | Q2: Per New Unit Sales SMR List - Opportunity Estavan | R2: Z003MCZR | S2: David Nordenmalm (Z003MCZR) | T2: 45642 | U2: Z003MCZR | V2: David Nordenmalm (Z003MCZR) | W2: 45642
A3: Sask Power GE-Hitachi- 300 MW Nuclear | B3: NR_RFP7406 | C3: RFP7406 | D3: RFP | E3: Included | F3: 300 MW Nuclear | G3: 2038 | H3: Saskatchewan (SK) | J3: MRO_Saskatchewan~57 | K3: Nuclear | M3: 300 | N3: 50557 | O3: SMR | Q3: Per New Unit Sales SMR List - Opportunity Estavan | R3: Z003MCZR | S3: David Nordenmalm (Z003MCZR) | T3: 45642 | U3: Z003MCZR | V3: David Nordenmalm (Z003MCZR) | W3: 45642
A4: Sask Power Westinghouse - 300 MW Nuclear | B4: NR_RFP7402 | C4: RFP7402 | D4: RFP | E4: Included | F4: 300 MW Nuclear | G4: 2038 | H4: Saskatchewan (SK) | J4: MRO_Saskatchewan~57 | K4: Nuclear | M4: 300 | N4: 50557 | O4: SMR | Q4: Per New Unit Sales SMR List | R4: Z003MCZR | S4: David Nordenmalm (Z003MCZR) | T4: 45642 | U4: Z003MCZR | V4: David Nordenmalm (Z003MCZR) | W4: 45642
A5: Sask Power GE-Hitachi- 300 MW Nuclear | B5: NR_RFP7407 | C5: RFP7407 | D5: RFP | E5: Included | F5: 300 MW Nuclear | G5: 2039 | H5: Saskatchewan (SK) | J5: MRO_Saskatchewan~57 | K5: Nuclear | M5: 300 | N5: 50922 | O5: SMR | Q5: Per New Unit Sales SMR List - Opportunity Estavan | R5: Z003MCZR | S5: David Nordenmalm (Z003MCZR) | T5: 45642 | U5: Z003MCZR | V5: David Nordenmalm (Z003MCZR) | W5: 45642
A6: Sask Power Westinghouse - 300 MW Nuclear | B6: NR_RFP7403 | C6: RFP7403 | D6: RFP | E6: Included | F6: 300 MW Nuclear | G6: 2039 | H6: Saskatchewan (SK) | J6: MRO_Saskatchewan~57 | K6: Nuclear | M6: 300 | N6: 50922 | O6: SMR | Q6: Per New Unit Sales SMR List | R6: Z003MCZR | S6: David Nordenmalm (Z003MCZR) | T6: 45642 | U6: Z003MCZR | V6: David Nordenmalm (Z003MCZR) | W6: 45642
A7: Sask Power GE-Hitachi- 300 MW Nuclear | B7: NR_RFP7408 | C7: RFP7408 | D7: RFP | E7: Included | F7: 300 MW Nuclear | G7: 2040 | H7: Saskatchewan (SK) | J7: MRO_Saskatchewan~57 | K7: Nuclear | M7: 300 | N7: 51288 | O7: SMR | Q7: Per New Unit Sales SMR List - Opportunity Estavan | R7: Z003MCZR | S7: David Nordenmalm (Z003MCZR) | T7: 45642 | U7: Z003MCZR | V7: David Nordenmalm (Z003MCZR) | W7: 45642
A8: Sask Power Westinghouse - 300 MW Nuclear | B8: NR_RFP7404 | C8: RFP7404 | D8: RFP | E8: Included | F8: 300 MW Nuclear | G8: 2040 | H8: Saskatchewan (SK) | J8: MRO_Saskatchewan~57 | K8: Nuclear | M8: 300 | N8: 51288 | O8: SMR | Q8: Per New Unit Sales SMR List | R8: Z003MCZR | S8: David Nordenmalm (Z003MCZR) | T8: 45642 | U8: Z003MCZR | V8: David Nordenmalm (Z003MCZR) | W8: 45642
A9: Darlington East Unit 1 - 1000 MW Nuclear | B9: NR_RFP7395 | C9: RFP7395 | D9: RFP | E9: Included | F9: 1000 MW Nuclear | G9: 2040 | H9: ON | J9: NPCC_Ontario_East~36 | K9: Nuclear | M9: 1000 | N9: 51288 | O9: Nuclear | Q9: Per Sales New Unit SMR List | R9: Z003MCZR | S9: David Nordenmalm (Z003MCZR) | T9: 45639 | U9: Z003MCZR | V9: David Nordenmalm (Z003MCZR) | W9: 45639
A10: Darlington East Unit 2 - 1000 MW Nuclear | B10: NR_RFP7396 | C10: RFP7396 | D10: RFP | E10: Included | F10: 1000 MW Nuclear | G10: 2041 | H10: ON | J10: NPCC_Ontario_East~36 | K10: Nuclear | M10: 1000 | N10: 51653 | O10: Nuclear | Q10: Per Sales New Unit SMR List | R10: Z003MCZR | S10: David Nordenmalm (Z003MCZR) | T10: 45639 | U10: Z003MCZR | V10: David Nordenmalm (Z003MCZR) | W10: 45639
A11: Darlington East Unit 3 - 1000 MW Nuclear | B11: NR_RFP7397 | C11: RFP7397 | D11: RFP | E11: Included | F11: 1000 MW Nuclear | G11: 2042 | H11: ON | J11: NPCC_Ontario_East~36 | K11: Nuclear | M11: 1000 | N11: 52018 | O11: Nuclear | Q11: Per Sales New Unit SMR List | R11: Z003MCZR | S11: David Nordenmalm (Z003MCZR) | T11: 45639 | U11: Z003MCZR | V11: David Nordenmalm (Z003MCZR) | W11: 45639
A12: Lambton Unit 1 - 1100 MW Nuclear | B12: NR_RFP9521 | C12: RFP9521 | D12: RFP | E12: Included | F12: 1100 MW Nuclear | G12: 2043 | H12: ON | I12: St. Clair | J12: NPCC_Ontario_West~33 | K12: Nuclear | M12: 1100 | N12: 52383 | O12: Nuclear | Q12: New Unit Sales and OPG Power Plan | R12: Z003MCZR | S12: David Nordenmalm (Z003MCZR) | T12: 45881 | U12: Z003MCZR | V12: David Nordenmalm (Z003MCZR) | W12: 45971
A13: Darlington East Unit 4 - 1000 MW Nuclear | B13: NR_RFP7398 | C13: RFP7398 | D13: RFP | E13: Included | F13: 1000 MW Nuclear | G13: 2043 | H13: ON | J13: NPCC_Ontario_East~36 | K13: Nuclear | M13: 1000 | N13: 52383 | O13: Nuclear | Q13: Per Sales New Unit SMR List | R13: Z003MCZR | S13: David Nordenmalm (Z003MCZR) | T13: 45639 | U13: Z003MCZR | V13: David Nordenmalm (Z003MCZR) | W13: 45639
A14: Lambton Unit 2 - 1100 MW Nuclear | B14: NR_RFP9522 | C14: RFP9522 | D14: RFP | E14: Included | F14: 1100 MW Nuclear | G14: 2044 | H14: ON | I14: St. Clair | J14: NPCC_Ontario_West~33 | K14: Nuclear | M14: 1100 | N14: 52749 | O14: Nuclear | Q14: New Unit Sales and OPG Power Plan | R14: Z003MCZR | S14: David Nordenmalm (Z003MCZR) | T14: 45881 | U14: Z003MCZR | V14: David Nordenmalm (Z003MCZR) | W14: 45971
A15: Wesleyville Unit 5 - 1100 MW Nuclear | B15: NR_RFP9517 | C15: RFP9517 | D15: RFP | E15: Included | F15: 1100 MW Nuclear | G15: 2044 | H15: ON | I15: Port Hope | J15: ~16 | K15: Nuclear | M15: 1100 | N15: 52749 | O15: Nuclear | Q15: Per OPG publication | R15: Z003MCZR | S15: David Nordenmalm (Z003MCZR) | T15: 45881 | U15: Z003MCZR | V15: David Nordenmalm (Z003MCZR) | W15: 45971
A16: Wesleyville Unit 6 - 1100 MW Nuclear | B16: NR_RFP9518 | C16: RFP9518 | D16: RFP | E16: Included | F16: 1100 MW Nuclear | G16: 2045 | H16: ON | I16: Port Hope | J16: ~16 | K16: Nuclear | M16: 1100 | N16: 53114 | O16: Nuclear | Q16: Per OPG publication | R16: Z003MCZR | S16: David Nordenmalm (Z003MCZR) | T16: 45881 | U16: Z003MCZR | V16: David Nordenmalm (Z003MCZR) | W16: 45971
A17: Wesleyville Unit 7 - 1100 MW Nuclear | B17: NR_RFP9519 | C17: RFP9519 | D17: RFP | E17: Included | F17: 1100 MW Nuclear | G17: 2046 | H17: ON | I17: Port Hope | J17: ~16 | K17: Nuclear | M17: 1100 | N17: 53479 | O17: Nuclear | Q17: Per OPG publication | R17: Z003MCZR | S17: David Nordenmalm (Z003MCZR) | T17: 45881 | U17: Z003MCZR | V17: David Nordenmalm (Z003MCZR) | W17: 45971
A18: Wesleyville Unit 8 - 1100 MW Nuclear | B18: NR_RFP9520 | C18: RFP9520 | D18: RFP | E18: Included | F18: 1100 MW Nuclear | G18: 2047 | H18: ON | I18: Port Hope | J18: ~16 | K18: Nuclear | M18: 1100 | N18: 53844 | O18: Nuclear | Q18: Per OPG publication | R18: Z003MCZR | S18: David Nordenmalm (Z003MCZR) | T18: 45881 | U18: Z003MCZR | V18: David Nordenmalm (Z003MCZR) | W18: 45971

Sheet Uprates
A1: Power Plant Unit Key | B1: Power Plant Key | C1: Plant Name | D1: Unit Name | E1: Fuel Type | F1: Nameplate Capacity Mw | G1: Summer Value | H1: Winter Value | I1: Calculated Uprate Value | J1: Upgrade Source | K1: Upgrade Type | L1: Upgrade Date | M1: Status | N1: Upgrade Comments | O1: Created Date | P1: Created User | Q1: Updated Date | R1: Updated User
A2: 22334 | B2: 1982 | C2: Bruce A | D2: Bruce CDU 1 | E2: Nuclear | F2: 805 | G2: 75 MW | H2: 75 | I2: =F2+H2 -> 880 | J2: Manual | K2: Uprate | L2: 47635 | M2: Active | N2: Per Article Bruce Units will receive a 600MW Site Uprate under Project 2030 - https://www.capitaliq.spglobal.com/web/client?auth=inherit#news/article?KeyProductLinkType=2&id=88800522 | O2: 45779 | P2: David Nordenmalm (Z003MCZR) | Q2: 45939 | R2: GRINH00P
A3: 28828 | B3: 1982 | C3: Bruce A | D3: Bruce CDU 3 | E3: Nuclear | F3: 805 | G3: 75 MW | H3: 75 | I3: =F3+H3 -> 880 | J3: Manual | K3: Uprate | L3: 47635 | M3: Active | N3: Per Article Bruce Units will receive a 600MW Site Uprate under Project 2030 - https://www.capitaliq.spglobal.com/web/client?auth=inherit#news/article?KeyProductLinkType=2&id=88800522 | O3: 45779 | P3: David Nordenmalm (Z003MCZR) | Q3: 45939 | R3: GRINH00P
A4: 28829 | B4: 1982 | C4: Bruce A | D4: Bruce CDU 2 | E4: Nuclear | F4: 805 | G4: 75 MW | H4: 75 | I4: =F4+H4 -> 880 | J4: Manual | K4: Uprate | L4: 47635 | M4: Active | N4: Per Article Bruce Units will receive a 600MW Site Uprate under Project 2030 - https://www.capitaliq.spglobal.com/web/client?auth=inherit#news/article?KeyProductLinkType=2&id=88800522 | O4: 45779 | P4: David Nordenmalm (Z003MCZR) | Q4: 45939 | R4: GRINH00P
A5: 28830 | B5: 1982 | C5: Bruce A | D5: Bruce CDU 4 | E5: Nuclear | F5: 805 | G5: 75 MW | H5: 75 | I5: =F5+H5 -> 880 | J5: Manual | K5: Uprate | L5: 58593 | M5: Active | N5: Per Article Bruce Units will receive a 600MW Site Uprate under Project 2030 - https://www.capitaliq.spglobal.com/web/client?auth=inherit#news/article?KeyProductLinkType=2&id=88800522 | O5: 45779 | P5: David Nordenmalm (Z003MCZR) | Q5: 45939 | R5: GRINH00P
A6: 22335 | B6: 1983 | C6: Bruce B | D6: Bruce CDU 8 | E6: Nuclear | F6: 840 | G6: 75 MW | H6: 75 | I6: =F6+H6 -> 915 | J6: Manual | K6: Uprate | L6: 47635 | M6: Active | N6: Per Article Bruce Units will receive a 600MW Site Uprate under Project 2030 - https://www.capitaliq.spglobal.com/web/client?auth=inherit#news/article?KeyProductLinkType=2&id=88800522 | O6: 45779 | P6: David Nordenmalm (Z003MCZR) | Q6: 45939 | R6: GRINH00P
A7: 28824 | B7: 1983 | C7: Bruce B | D7: Bruce CDU 5 | E7: Nuclear | F7: 840 | G7: 75 MW | H7: 75 | I7: =F7+H7 -> 915 | J7: Manual | K7: Uprate | L7: 47635 | M7: Active | N7: Per Article Bruce Units will receive a 600MW Site Uprate under Project 2030 - https://www.capitaliq.spglobal.com/web/client?auth=inherit#news/article?KeyProductLinkType=2&id=88800522 | O7: 45779 | P7: David Nordenmalm (Z003MCZR) | Q7: 45939 | R7: GRINH00P
A8: 28825 | B8: 1983 | C8: Bruce B | D8: Bruce CDU 6 | E8: Nuclear | F8: 870 | G8: 75 MW | H8: 75 | I8: =F8+H8 -> 945 | J8: Manual | K8: Uprate | L8: 47635 | M8: Active | N8: Per Article Bruce Units will receive a 600MW Site Uprate under Project 2030 - https://www.capitaliq.spglobal.com/web/client?auth=inherit#news/article?KeyProductLinkType=2&id=88800522 | O8: 45779 | P8: David Nordenmalm (Z003MCZR) | Q8: 45939 | R8: GRINH00P
A9: 28826 | B9: 1983 | C9: Bruce B | D9: Bruce CDU 7 | E9: Nuclear | F9: 840 | G9: 75 MW | H9: 75 | I9: =F9+H9 -> 915 | J9: Manual | K9: Uprate | L9: 47635 | M9: Active | N9: Per Article Bruce Units will receive a 600MW Site Uprate under Project 2030 - https://www.capitaliq.spglobal.com/web/client?auth=inherit#news/article?KeyProductLinkType=2&id=88800522 | O9: 45779 | P9: David Nordenmalm (Z003MCZR) | Q9: 45939 | R9: GRINH00P

Sheet A&R Pivot
A3: Row Labels | B3: Sum of Unit Nameplate Capacity
A4: 1977 | B4: 1610
A5: 1978 | B5: 805
A6: 1979 | B6: 805
A7: 1983 | B7: 1992
A8: 1984 | B8: 1387
A9: 1985 | B9: 1357
A10: 1986 | B10: 1357
A11: 1990 | B11: 934
A12: 1992 | B12: 1868
A13: 1993 | B13: 934
A14: 2028 | B14: 5
A15: 2030 | B15: 600
... A29: Grand Total | B29: 35229

Sheet IRP & RFP Pivot
A3: Row Labels | B3: Sum of Current Operating Capacity
A4: 2037 | B4: 300
A5: 2038 | B5: 600
A6: 2039 | B6: 600
A7: 2040 | B7: 1600
A8: 2041 | B8: 1000
A9: 2042 | B9: 1000
A10: 2043 | B10: 2100
A11: 2044 | B11: 2200
A12: 2045 | B12: 1100
A13: 2046 | B13: 1100
A14: 2047 | B14: 1100
A15: Grand Total | B15: 12700

Sheet Uprates Pivot
A3: Row Labels | B3: Sum of Winter Value
A4: 2030 | B4: 525
A5: 2060 | B5: 75
A6: Grand Total | B6: 600
