Workbook

Sheet Cover
A1: Power Demand Model
A3: Model version: | B3: ef58fe6 (2026-07-07 15:25) [dirty] + cooling split and climate adjustment (2026-10-23)
A4: Scenario: | B4: FEL 2026 | Base FEL | Base
A6: Scenario Parameters
A7: Parameter | B7: Preset | C7: Scaling
A8: BEV share of vehicle sales | B8: base_fel | C8: 1
A9: Buildings scenario | B9: base_fel
A10: Industry scenario | B10: base_fel | C10: 1
A11: Industry electrification — Iron & Steel | B11: base_fel | C11: 1
A12: Industry electrification — Chemicals | B12: base_fel | C12: 1
A13: Industry electrification — Other | B13: base_fel | C13: 1
A14: Data center scenario | B14: base_fel
A15: DC BTM/FTM sensitivity | B15: base_fel
A16: Hydrogen scenario | B16: base_fel
A17: Energy efficiency improvements | B17: base_fel | C17: 1
A18: GDP growth | B18: base_fel | C18: 1
A19: Power prices | B19: base_fel | C19: 1
A20: Transport scenario | B20: base_fel
A21: US transport BEV scenario | B21: base_fel
A22: Cooling split (own sector) | B22: pdm_2026-09-23
A23: Physical climate pathway (cooling/heating, NA) | B23: ssp245 + COP
A24: AC adoption from warmer summers | B24: mcneil_gap_closure
A26: Geographies: | B26: US, DE, FR, IT, ES, UK, PL, CA, US_R_CALIFORNIA, US_R_ERCOT, US_R_PJM, US_R_WECC, US_R_SPP, US_R_MISO, US_R_SERC, US_R_NYISO, US_R_ISONE
A27: Years: | B27: 2024-2040
A29: Generated by Python Power Demand Model v1.0
A30: Cooling split out of buildings for US and Canada only; Europe unchanged vs v260707_v2.

Sheet Dashboard
A1: Dashboard
A2: Scenario: FEL 2026 | Base FEL | Base
A5: Geography | B5: 2024 | C5: 2025 | D5: 2026 | E5: 2027 | F5: 2028 | G5: 2029 | H5: 2030 | I5: 2031 | J5: 2032 | K5: 2033 | L5: 2034 | M5: 2035 | N5: 2036 | O5: 2037 | P5: 2038 | Q5: 2039 | R5: 2040
A6: EU28 | B6: =SUMIFS(_Data_Sectoral!$F$2:$F$20000,_Data_Sectoral!$A$2:$A$20000,"EU28",_Data_Sectoral!$D$2:$D$20000,"TOTAL",_Data_Sectoral!$E$2:$E$20000,2024) -> 2757.9599 | C6: =SUMIFS(_Data_Sectoral!$F$2:$F$20000,_Data_Sectoral!$A$2:$A$20000,"EU28",_Data_Sectoral!$D$2:$D$20000,"TOTAL",_Data_Sectoral!$E$2:$E$20000,2025) -> 2799.6018 | D6: =SUMIFS(_Data_Sectoral!$F$2:$F$20000,_Data_Sectoral!$A$2:$A$20000,"EU28",_Data_Sectoral!$D$2:$D$20000,"TOTAL",_Data_Sectoral!$E$2:$E$20000,2026) -> 2853.0276 | E6: =SUMIFS(_Data_Sectoral!$F$2:$F$20000,_Data_Sectoral!$A$2:$A$20000,"EU28",_Data_Sectoral!$D$2:$D$20000,"TOTAL",_Data_Sectoral!$E$2:$E$20000,2027) -> 2917.1644 | F6: =SUMIFS(_Data_Sectoral!$F$2:$F$20000,_Data_Sectoral!$A$2:$A$20000,"EU28",_Data_Sectoral!$D$2:$D$20000,"TOTAL",_Data_Sectoral!$E$2:$E$20000,2028) -> 2984.5584 | G6: =SUMIFS(_Data_Sectoral!$F$2:$F$20000,_Data_Sectoral!$A$2:$A$20000,"EU28",_Data_Sectoral!$D$2:$D$20000,"TOTAL",_Data_Sectoral!$E$2:$E$20000,2029) -> 3066.2688 | H6: =SUMIFS(_Data_Sectoral!$F$2:$F$20000,_Data_Sectoral!$A$2:$A$20000,"EU28",_Data_Sectoral!$D$2:$D$20000,"TOTAL",_Data_Sectoral!$E$2:$E$20000,2030) -> 3142.9569 | I6: =SUMIFS(_Data_Sectoral!$F$2:$F$20000,_Data_Sectoral!$A$2:$A$20000,"EU28",_Data_Sectoral!$D$2:$D$20000,"TOTAL",_Data_Sectoral!$E$2:$E$20000,2031) -> 3220.6043 | J6: =SUMIFS(_Data_Sectoral!$F$2:$F$20000,_Data_Sectoral!$A$2:$A$20000,"EU28",_Data_Sectoral!$D$2:$D$20000,"TOTAL",_Data_Sectoral!$E$2:$E$20000,2032) -> 3314.8918 | K6: =SUMIFS(_Data_Sectoral!$F$2:$F$20000,_Data_Sectoral!$A$2:$A$20000,"EU28",_Data_Sectoral!$D$2:$D$20000,"TOTAL",_Data_Sectoral!$E$2:$E$20000,2033) -> 3415.3326 | L6: =SUMIFS(_Data_Sectoral!$F$2:$F$20000,_Data_Sectoral!$A$2:$A$20000,"EU28",_Data_Sectoral!$D$2:$D$20000,"TOTAL",_Data_Sectoral!$E$2:$E$20000,2034) -> 3520.4642 | M6: =SUMIFS(_Data_Sectoral!$F$2:$F$20000,_Data_Sectoral!$A$2:$A$20000,"EU28",_Data_Sectoral!$D$2:$D$20000,"TOTAL",_Data_Sectoral!$E$2:$E$20000,2035) -> 3626.9258 | N6: =SUMIFS(_Data_Sectoral!$F$2:$F$20000,_Data_Sectoral!$A$2:$A$20000,"EU28",_Data_Sectoral!$D$2:$D$20000,"TOTAL",_Data_Sectoral!$E$2:$E$20000,2036) -> 3724.5284 | O6: =SUMIFS(_Data_Sectoral!$F$2:$F$20000,_Data_Sectoral!$A$2:$A$20000,"EU28",_Data_Sectoral!$D$2:$D$20000,"TOTAL",_Data_Sectoral!$E$2:$E$20000,2037) -> 3813.6523 | P6: =SUMIFS(_Data_Sectoral!$F$2:$F$20000,_Data_Sectoral!$A$2:$A$20000,"EU28",_Data_Sectoral!$D$2:$D$20000,"TOTAL",_Data_Sectoral!$E$2:$E$20000,2038) -> 3901.5097 | Q6: =SUMIFS(_Data_Sectoral!$F$2:$F$20000,_Data_Sectoral!$A$2:$A$20000,"EU28",_Data_Sectoral!$D$2:$D$20000,"TOTAL",_Data_Sectoral!$E$2:$E$20000,2039) -> 3987.5668 | R6: =SUMIFS(_Data_Sectoral!$F$2:$F$20000,_Data_Sectoral!$A$2:$A$20000,"EU28",_Data_Sectoral!$D$2:$D$20000,"TOTAL",_Data_Sectoral!$E$2:$E$20000,2040) -> 4069.837
A7: United States | B7: =SUMIFS(_Data_Sectoral!$F$2:$F$20000,_Data_Sectoral!$A$2:$A$20000,"US",_Data_Sectoral!$D$2:$D$20000,"TOTAL",_Data_Sectoral!$E$2:$E$20000,2024) -> 4155.0351 | C7: =SUMIFS(_Data_Sectoral!$F$2:$F$20000,_Data_Sectoral!$A$2:$A$20000,"US",_Data_Sectoral!$D$2:$D$20000,"TOTAL",_Data_Sectoral!$E$2:$E$20000,2025) -> 4209.9341 | D7: =SUMIFS(_Data_Sectoral!$F$2:$F$20000,_Data_Sectoral!$A$2:$A$20000,"US",_Data_Sectoral!$D$2:$D$20000,"TOTAL",_Data_Sectoral!$E$2:$E$20000,2026) -> 4300.1163 | E7: =SUMIFS(_Data_Sectoral!$F$2:$F$20000,_Data_Sectoral!$A$2:$A$20000,"US",_Data_Sectoral!$D$2:$D$20000,"TOTAL",_Data_Sectoral!$E$2:$E$20000,2027) -> 4466.5673 | F7: =SUMIFS(_Data_Sectoral!$F$2:$F$20000,_Data_Sectoral!$A$2:$A$20000,"US",_Data_Sectoral!$D$2:$D$20000,"TOTAL",_Data_Sectoral!$E$2:$E$20000,2028) -> 4661.3521 | G7: =SUMIFS(_Data_Sectoral!$F$2:$F$20000,_Data_Sectoral!$A$2:$A$20000,"US",_Data_Sectoral!$D$2:$D$20000,"TOTAL",_Data_Sectoral!$E$2:$E$20000,2029) -> 4874.7992 | H7: =SUMIFS(_Data_Sectoral!$F$2:$F$20000,_Data_Sectoral!$A$2:$A$20000,"US",_Data_Sectoral!$D$2:$D$20000,"TOTAL",_Data_Sectoral!$E$2:$E$20000,2030) -> 5112.4056 | I7: =SUMIFS(_Data_Sectoral!$F$2:$F$20000,_Data_Sectoral!$A$2:$A$20000,"US",_Data_Sectoral!$D$2:$D$20000,"TOTAL",_Data_Sectoral!$E$2:$E$20000,2031) -> 5392.5459 | J7: =SUMIFS(_Data_Sectoral!$F$2:$F$20000,_Data_Sectoral!$A$2:$A$20000,"US",_Data_Sectoral!$D$2:$D$20000,"TOTAL",_Data_Sectoral!$E$2:$E$20000,2032) -> 5684.3229 | K7: =SUMIFS(_Data_Sectoral!$F$2:$F$20000,_Data_Sectoral!$A$2:$A$20000,"US",_Data_Sectoral!$D$2:$D$20000,"TOTAL",_Data_Sectoral!$E$2:$E$20000,2033) -> 5941.2239 | L7: =SUMIFS(_Data_Sectoral!$F$2:$F$20000,_Data_Sectoral!$A$2:$A$20000,"US",_Data_Sectoral!$D$2:$D$20000,"TOTAL",_Data_Sectoral!$E$2:$E$20000,2034) -> 6219.8223 | M7: =SUMIFS(_Data_Sectoral!$F$2:$F$20000,_Data_Sectoral!$A$2:$A$20000,"US",_Data_Sectoral!$D$2:$D$20000,"TOTAL",_Data_Sectoral!$E$2:$E$20000,2035) -> 6483.1681 | N7: =SUMIFS(_Data_Sectoral!$F$2:$F$20000,_Data_Sectoral!$A$2:$A$20000,"US",_Data_Sectoral!$D$2:$D$20000,"TOTAL",_Data_Sectoral!$E$2:$E$20000,2036) -> 6743.1581 | O7: =SUMIFS(_Data_Sectoral!$F$2:$F$20000,_Data_Sectoral!$A$2:$A$20000,"US",_Data_Sectoral!$D$2:$D$20000,"TOTAL",_Data_Sectoral!$E$2:$E$20000,2037) -> 7007.522 | P7: =SUMIFS(_Data_Sectoral!$F$2:$F$20000,_Data_Sectoral!$A$2:$A$20000,"US",_Data_Sectoral!$D$2:$D$20000,"TOTAL",_Data_Sectoral!$E$2:$E$20000,2038) -> 7255.4984 | Q7: =SUMIFS(_Data_Sectoral!$F$2:$F$20000,_Data_Sectoral!$A$2:$A$20000,"US",_Data_Sectoral!$D$2:$D$20000,"TOTAL",_Data_Sectoral!$E$2:$E$20000,2039) -> 7500.2592 | R7: =SUMIFS(_Data_Sectoral!$F$2:$F$20000,_Data_Sectoral!$A$2:$A$20000,"US",_Data_Sectoral!$D$2:$D$20000,"TOTAL",_Data_Sectoral!$E$2:$E$20000,2040) -> 7719.4272
A9: All Modeled | B9: =SUM(B6:B7) -> 6912.995 | C9: =SUM(C6:C7) -> 7009.5359 | D9: =SUM(D6:D7) -> 7153.1439 | E9: =SUM(E6:E7) -> 7383.7316 | F9: =SUM(F6:F7) -> 7645.9105 | G9: =SUM(G6:G7) -> 7941.0679 | H9: =SUM(H6:H7) -> 8255.3625 | I9: =SUM(I6:I7) -> 8613.1502 | ... R9: =SUM(R6:R7) -> 11789.264
A12: Germany
A13: Sector | B13: 2024 | C13: 2025 | D13: 2026 | E13: 2027 | F13: 2028 | G13: 2029 | H13: 2030 | I13: 2031 | J13: 2032 | K13: 2033 | L13: 2034 | M13: 2035 | N13: 2036 | O13: 2037 | P13: 2038 | Q13: 2039 | R13: 2040
A14: Transport | B14: =SUMIFS(_Data_Sectoral!$F$2:$F$20000,_Data_Sectoral!$A$2:$A$20000,"DE",_Data_Sectoral!$C$2:$C$20000,"transport",_Data_Sectoral!$D$2:$D$20000,"TOTAL",_Data_Sectoral!$E$2:$E$20000,2024) -> 19.997696 | C14: =SUMIFS(_Data_Sectoral!$F$2:$F$20000,_Data_Sectoral!$A$2:$A$20000,"DE",_Data_Sectoral!$C$2:$C$20000,"transport",_Data_Sectoral!$D$2:$D$20000,"TOTAL",_Data_Sectoral!$E$2:$E$20000,2025) -> 21.931835 | D14: =SUMIFS(_Data_Sectoral!$F$2:$F$20000,_Data_Sectoral!$A$2:$A$20000,"DE",_Data_Sectoral!$C$2:$C$20000,"transport",_Data_Sectoral!$D$2:$D$20000,"TOTAL",_Data_Sectoral!$E$2:$E$20000,2026) -> 24.37738 | E14: =SUMIFS(_Data_Sectoral!$F$2:$F$20000,_Data_Sectoral!$A$2:$A$20000,"DE",_Data_Sectoral!$C$2:$C$20000,"transport",_Data_Sectoral!$D$2:$D$20000,"TOTAL",_Data_Sectoral!$E$2:$E$20000,2027) -> 27.716301 | F14: =SUMIFS(_Data_Sectoral!$F$2:$F$20000,_Data_Sectoral!$A$2:$A$20000,"DE",_Data_Sectoral!$C$2:$C$20000,"transport",_Data_Sectoral!$D$2:$D$20000,"TOTAL",_Data_Sectoral!$E$2:$E$20000,2028) -> 31.834037 | G14: =SUMIFS(_Data_Sectoral!$F$2:$F$20000,_Data_Sectoral!$A$2:$A$20000,"DE",_Data_Sectoral!$C$2:$C$20000,"transport",_Data_Sectoral!$D$2:$D$20000,"TOTAL",_Data_Sectoral!$E$2:$E$20000,2029) -> 36.865139 | H14: =SUMIFS(_Data_Sectoral!$F$2:$F$20000,_Data_Sectoral!$A$2:$A$20000,"DE",_Data_Sectoral!$C$2:$C$20000,"transport",_Data_Sectoral!$D$2:$D$20000,"TOTAL",_Data_Sectoral!$E$2:$E$20000,2030) -> 42.684968 | I14: =SUMIFS(_Data_Sectoral!$F$2:$F$20000,_Data_Sectoral!$A$2:$A$20000,"DE",_Data_Sectoral!$C$2:$C$20000,"transport",_Data_Sectoral!$D$2:$D$20000,"TOTAL",_Data_Sectoral!$E$2:$E$20000,2031) -> 48.93417 | J14: =SUMIFS(_Data_Sectoral!$F$2:$F$20000,_Data_Sectoral!$A$2:$A$20000,"DE",_Data_Sectoral!$C$2:$C$20000,"transport",_Data_Sectoral!$D$2:$D$20000,"TOTAL",_Data_Sectoral!$E$2:$E$20000,2032) -> 55.832518 | K14: =SUMIFS(_Data_Sectoral!$F$2:$F$20000,_Data_Sectoral!$A$2:$A$20000,"DE",_Data_Sectoral!$C$2:$C$20000,"transport",_Data_Sectoral!$D$2:$D$20000,"TOTAL",_Data_Sectoral!$E$2:$E$20000,2033) -> 63.240901 | L14: =SUMIFS(_Data_Sectoral!$F$2:$F$20000,_Data_Sectoral!$A$2:$A$20000,"DE",_Data_Sectoral!$C$2:$C$20000,"transport",_Data_Sectoral!$D$2:$D$20000,"TOTAL",_Data_Sectoral!$E$2:$E$20000,2034) -> 70.531404 | M14: =SUMIFS(_Data_Sectoral!$F$2:$F$20000,_Data_Sectoral!$A$2:$A$20000,"DE",_Data_Sectoral!$C$2:$C$20000,"transport",_Data_Sectoral!$D$2:$D$20000,"TOTAL",_Data_Sectoral!$E$2:$E$20000,2035) -> 77.872913 | N14: =SUMIFS(_Data_Sectoral!$F$2:$F$20000,_Data_Sectoral!$A$2:$A$20000,"DE",_Data_Sectoral!$C$2:$C$20000,"transport",_Data_Sectoral!$D$2:$D$20000,"TOTAL",_Data_Sectoral!$E$2:$E$20000,2036) -> 85.067542 | O14: =SUMIFS(_Data_Sectoral!$F$2:$F$20000,_Data_Sectoral!$A$2:$A$20000,"DE",_Data_Sectoral!$C$2:$C$20000,"transport",_Data_Sectoral!$D$2:$D$20000,"TOTAL",_Data_Sectoral!$E$2:$E$20000,2037) -> 91.891028 | P14: =SUMIFS(_Data_Sectoral!$F$2:$F$20000,_Data_Sectoral!$A$2:$A$20000,"DE",_Data_Sectoral!$C$2:$C$20000,"transport",_Data_Sectoral!$D$2:$D$20000,"TOTAL",_Data_Sectoral!$E$2:$E$20000,2038) -> 98.584437 | Q14: =SUMIFS(_Data_Sectoral!$F$2:$F$20000,_Data_Sectoral!$A$2:$A$20000,"DE",_Data_Sectoral!$C$2:$C$20000,"transport",_Data_Sectoral!$D$2:$D$20000,"TOTAL",_Data_Sectoral!$E$2:$E$20000,2039) -> 105.42056 | R14: =SUMIFS(_Data_Sectoral!$F$2:$F$20000,_Data_Sectoral!$A$2:$A$20000,"DE",_Data_Sectoral!$C$2:$C$20000,"transport",_Data_Sectoral!$D$2:$D$20000,"TOTAL",_Data_Sectoral!$E$2:$E$20000,2040) -> 110.96325
A15: Buildings | B15: =SUMIFS(_Data_Sectoral!$F$2:$F$20000,_Data_Sectoral!$A$2:$A$20000,"DE",_Data_Sectoral!$C$2:$C$20000,"buildings",_Data_Sectoral!$D$2:$D$20000,"TOTAL",_Data_Sectoral!$E$2:$E$20000,2024) -> 253.28661 | C15: =SUMIFS(_Data_Sectoral!$F$2:$F$20000,_Data_Sectoral!$A$2:$A$20000,"DE",_Data_Sectoral!$C$2:$C$20000,"buildings",_Data_Sectoral!$D$2:$D$20000,"TOTAL",_Data_Sectoral!$E$2:$E$20000,2025) -> 254.89252 | D15: =SUMIFS(_Data_Sectoral!$F$2:$F$20000,_Data_Sectoral!$A$2:$A$20000,"DE",_Data_Sectoral!$C$2:$C$20000,"buildings",_Data_Sectoral!$D$2:$D$20000,"TOTAL",_Data_Sectoral!$E$2:$E$20000,2026) -> 256.72996 | E15: =SUMIFS(_Data_Sectoral!$F$2:$F$20000,_Data_Sectoral!$A$2:$A$20000,"DE",_Data_Sectoral!$C$2:$C$20000,"buildings",_Data_Sectoral!$D$2:$D$20000,"TOTAL",_Data_Sectoral!$E$2:$E$20000,2027) -> 258.35599 | F15: =SUMIFS(_Data_Sectoral!$F$2:$F$20000,_Data_Sectoral!$A$2:$A$20000,"DE",_Data_Sectoral!$C$2:$C$20000,"buildings",_Data_Sectoral!$D$2:$D$20000,"TOTAL",_Data_Sectoral!$E$2:$E$20000,2028) -> 260.13162 | G15: =SUMIFS(_Data_Sectoral!$F$2:$F$20000,_Data_Sectoral!$A$2:$A$20000,"DE",_Data_Sectoral!$C$2:$C$20000,"buildings",_Data_Sectoral!$D$2:$D$20000,"TOTAL",_Data_Sectoral!$E$2:$E$20000,2029) -> 261.96654 | H15: =SUMIFS(_Data_Sectoral!$F$2:$F$20000,_Data_Sectoral!$A$2:$A$20000,"DE",_Data_Sectoral!$C$2:$C$20000,"buildings",_Data_Sectoral!$D$2:$D$20000,"TOTAL",_Data_Sectoral!$E$2:$E$20000,2030) -> 267.74692 | I15: =SUMIFS(_Data_Sectoral!$F$2:$F$20000,_Data_Sectoral!$A$2:$A$20000,"DE",_Data_Sectoral!$C$2:$C$20000,"buildings",_Data_Sectoral!$D$2:$D$20000,"TOTAL",_Data_Sectoral!$E$2:$E$20000,2031) -> 270.50928 | J15: =SUMIFS(_Data_Sectoral!$F$2:$F$20000,_Data_Sectoral!$A$2:$A$20000,"DE",_Data_Sectoral!$C$2:$C$20000,"buildings",_Data_Sectoral!$D$2:$D$20000,"TOTAL",_Data_Sectoral!$E$2:$E$20000,2032) -> 272.71494 | K15: =SUMIFS(_Data_Sectoral!$F$2:$F$20000,_Data_Sectoral!$A$2:$A$20000,"DE",_Data_Sectoral!$C$2:$C$20000,"buildings",_Data_Sectoral!$D$2:$D$20000,"TOTAL",_Data_Sectoral!$E$2:$E$20000,2033) -> 275.54347 | L15: =SUMIFS(_Data_Sectoral!$F$2:$F$20000,_Data_Sectoral!$A$2:$A$20000,"DE",_Data_Sectoral!$C$2:$C$20000,"buildings",_Data_Sectoral!$D$2:$D$20000,"TOTAL",_Data_Sectoral!$E$2:$E$20000,2034) -> 278.72443 | M15: =SUMIFS(_Data_Sectoral!$F$2:$F$20000,_Data_Sectoral!$A$2:$A$20000,"DE",_Data_Sectoral!$C$2:$C$20000,"buildings",_Data_Sectoral!$D$2:$D$20000,"TOTAL",_Data_Sectoral!$E$2:$E$20000,2035) -> 282.26729 | N15: =SUMIFS(_Data_Sectoral!$F$2:$F$20000,_Data_Sectoral!$A$2:$A$20000,"DE",_Data_Sectoral!$C$2:$C$20000,"buildings",_Data_Sectoral!$D$2:$D$20000,"TOTAL",_Data_Sectoral!$E$2:$E$20000,2036) -> 284.98655 | O15: =SUMIFS(_Data_Sectoral!$F$2:$F$20000,_Data_Sectoral!$A$2:$A$20000,"DE",_Data_Sectoral!$C$2:$C$20000,"buildings",_Data_Sectoral!$D$2:$D$20000,"TOTAL",_Data_Sectoral!$E$2:$E$20000,2037) -> 287.55782 | P15: =SUMIFS(_Data_Sectoral!$F$2:$F$20000,_Data_Sectoral!$A$2:$A$20000,"DE",_Data_Sectoral!$C$2:$C$20000,"buildings",_Data_Sectoral!$D$2:$D$20000,"TOTAL",_Data_Sectoral!$E$2:$E$20000,2038) -> 290.17914 | Q15: =SUMIFS(_Data_Sectoral!$F$2:$F$20000,_Data_Sectoral!$A$2:$A$20000,"DE",_Data_Sectoral!$C$2:$C$20000,"buildings",_Data_Sectoral!$D$2:$D$20000,"TOTAL",_Data_Sectoral!$E$2:$E$20000,2039) -> 291.86426 | R15: =SUMIFS(_Data_Sectoral!$F$2:$F$20000,_Data_Sectoral!$A$2:$A$20000,"DE",_Data_Sectoral!$C$2:$C$20000,"buildings",_Data_Sectoral!$D$2:$D$20000,"TOTAL",_Data_Sectoral!$E$2:$E$20000,2040) -> 293.54326
A16: Industry | B16: =SUMIFS(_Data_Sectoral!$F$2:$F$20000,_Data_Sectoral!$A$2:$A$20000,"DE",_Data_Sectoral!$C$2:$C$20000,"industry",_Data_Sectoral!$D$2:$D$20000,"TOTAL",_Data_Sectoral!$E$2:$E$20000,2024) -> 181.89842 | C16: =SUMIFS(_Data_Sectoral!$F$2:$F$20000,_Data_Sectoral!$A$2:$A$20000,"DE",_Data_Sectoral!$C$2:$C$20000,"industry",_Data_Sectoral!$D$2:$D$20000,"TOTAL",_Data_Sectoral!$E$2:$E$20000,2025) -> 183.47596 | D16: =SUMIFS(_Data_Sectoral!$F$2:$F$20000,_Data_Sectoral!$A$2:$A$20000,"DE",_Data_Sectoral!$C$2:$C$20000,"industry",_Data_Sectoral!$D$2:$D$20000,"TOTAL",_Data_Sectoral!$E$2:$E$20000,2026) -> 185.22682 | E16: =SUMIFS(_Data_Sectoral!$F$2:$F$20000,_Data_Sectoral!$A$2:$A$20000,"DE",_Data_Sectoral!$C$2:$C$20000,"industry",_Data_Sectoral!$D$2:$D$20000,"TOTAL",_Data_Sectoral!$E$2:$E$20000,2027) -> 189.37152 | F16: =SUMIFS(_Data_Sectoral!$F$2:$F$20000,_Data_Sectoral!$A$2:$A$20000,"DE",_Data_Sectoral!$C$2:$C$20000,"industry",_Data_Sectoral!$D$2:$D$20000,"TOTAL",_Data_Sectoral!$E$2:$E$20000,2028) -> 192.01958 | G16: =SUMIFS(_Data_Sectoral!$F$2:$F$20000,_Data_Sectoral!$A$2:$A$20000,"DE",_Data_Sectoral!$C$2:$C$20000,"industry",_Data_Sectoral!$D$2:$D$20000,"TOTAL",_Data_Sectoral!$E$2:$E$20000,2029) -> 195.35985 | H16: =SUMIFS(_Data_Sectoral!$F$2:$F$20000,_Data_Sectoral!$A$2:$A$20000,"DE",_Data_Sectoral!$C$2:$C$20000,"industry",_Data_Sectoral!$D$2:$D$20000,"TOTAL",_Data_Sectoral!$E$2:$E$20000,2030) -> 198.88547 | I16: =SUMIFS(_Data_Sectoral!$F$2:$F$20000,_Data_Sectoral!$A$2:$A$20000,"DE",_Data_Sectoral!$C$2:$C$20000,"industry",_Data_Sectoral!$D$2:$D$20000,"TOTAL",_Data_Sectoral!$E$2:$E$20000,2031) -> 203.52721 | J16: =SUMIFS(_Data_Sectoral!$F$2:$F$20000,_Data_Sectoral!$A$2:$A$20000,"DE",_Data_Sectoral!$C$2:$C$20000,"industry",_Data_Sectoral!$D$2:$D$20000,"TOTAL",_Data_Sectoral!$E$2:$E$20000,2032) -> 208.68291 | K16: =SUMIFS(_Data_Sectoral!$F$2:$F$20000,_Data_Sectoral!$A$2:$A$20000,"DE",_Data_Sectoral!$C$2:$C$20000,"industry",_Data_Sectoral!$D$2:$D$20000,"TOTAL",_Data_Sectoral!$E$2:$E$20000,2033) -> 213.63744 | L16: =SUMIFS(_Data_Sectoral!$F$2:$F$20000,_Data_Sectoral!$A$2:$A$20000,"DE",_Data_Sectoral!$C$2:$C$20000,"industry",_Data_Sectoral!$D$2:$D$20000,"TOTAL",_Data_Sectoral!$E$2:$E$20000,2034) -> 218.7088 | M16: =SUMIFS(_Data_Sectoral!$F$2:$F$20000,_Data_Sectoral!$A$2:$A$20000,"DE",_Data_Sectoral!$C$2:$C$20000,"industry",_Data_Sectoral!$D$2:$D$20000,"TOTAL",_Data_Sectoral!$E$2:$E$20000,2035) -> 223.93116 | N16: =SUMIFS(_Data_Sectoral!$F$2:$F$20000,_Data_Sectoral!$A$2:$A$20000,"DE",_Data_Sectoral!$C$2:$C$20000,"industry",_Data_Sectoral!$D$2:$D$20000,"TOTAL",_Data_Sectoral!$E$2:$E$20000,2036) -> 225.73092 | O16: =SUMIFS(_Data_Sectoral!$F$2:$F$20000,_Data_Sectoral!$A$2:$A$20000,"DE",_Data_Sectoral!$C$2:$C$20000,"industry",_Data_Sectoral!$D$2:$D$20000,"TOTAL",_Data_Sectoral!$E$2:$E$20000,2037) -> 227.52973 | P16: =SUMIFS(_Data_Sectoral!$F$2:$F$20000,_Data_Sectoral!$A$2:$A$20000,"DE",_Data_Sectoral!$C$2:$C$20000,"industry",_Data_Sectoral!$D$2:$D$20000,"TOTAL",_Data_Sectoral!$E$2:$E$20000,2038) -> 229.19499 | Q16: =SUMIFS(_Data_Sectoral!$F$2:$F$20000,_Data_Sectoral!$A$2:$A$20000,"DE",_Data_Sectoral!$C$2:$C$20000,"industry",_Data_Sectoral!$D$2:$D$20000,"TOTAL",_Data_Sectoral!$E$2:$E$20000,2039) -> 231.26294 | R16: =SUMIFS(_Data_Sectoral!$F$2:$F$20000,_Data_Sectoral!$A$2:$A$20000,"DE",_Data_Sectoral!$C$2:$C$20000,"industry",_Data_Sectoral!$D$2:$D$20000,"TOTAL",_Data_Sectoral!$E$2:$E$20000,2040) -> 232.33639
A17: Data Centers | B17: =SUMIFS(_Data_Sectoral!$F$2:$F$20000,_Data_Sectoral!$A$2:$A$20000,"DE",_Data_Sectoral!$C$2:$C$20000,"data_centers",_Data_Sectoral!$D$2:$D$20000,"TOTAL",_Data_Sectoral!$E$2:$E$20000,2024) -> 19.99887 | C17: =SUMIFS(_Data_Sectoral!$F$2:$F$20000,_Data_Sectoral!$A$2:$A$20000,"DE",_Data_Sectoral!$C$2:$C$20000,"data_centers",_Data_Sectoral!$D$2:$D$20000,"TOTAL",_Data_Sectoral!$E$2:$E$20000,2025) -> 21.295244 | D17: =SUMIFS(_Data_Sectoral!$F$2:$F$20000,_Data_Sectoral!$A$2:$A$20000,"DE",_Data_Sectoral!$C$2:$C$20000,"data_centers",_Data_Sectoral!$D$2:$D$20000,"TOTAL",_Data_Sectoral!$E$2:$E$20000,2026) -> 24.136782 | E17: =SUMIFS(_Data_Sectoral!$F$2:$F$20000,_Data_Sectoral!$A$2:$A$20000,"DE",_Data_Sectoral!$C$2:$C$20000,"data_centers",_Data_Sectoral!$D$2:$D$20000,"TOTAL",_Data_Sectoral!$E$2:$E$20000,2027) -> 27.201716 | F17: =SUMIFS(_Data_Sectoral!$F$2:$F$20000,_Data_Sectoral!$A$2:$A$20000,"DE",_Data_Sectoral!$C$2:$C$20000,"data_centers",_Data_Sectoral!$D$2:$D$20000,"TOTAL",_Data_Sectoral!$E$2:$E$20000,2028) -> 30.64595 | G17: =SUMIFS(_Data_Sectoral!$F$2:$F$20000,_Data_Sectoral!$A$2:$A$20000,"DE",_Data_Sectoral!$C$2:$C$20000,"data_centers",_Data_Sectoral!$D$2:$D$20000,"TOTAL",_Data_Sectoral!$E$2:$E$20000,2029) -> 33.833232 | H17: =SUMIFS(_Data_Sectoral!$F$2:$F$20000,_Data_Sectoral!$A$2:$A$20000,"DE",_Data_Sectoral!$C$2:$C$20000,"data_centers",_Data_Sectoral!$D$2:$D$20000,"TOTAL",_Data_Sectoral!$E$2:$E$20000,2030) -> 36.20331 | I17: =SUMIFS(_Data_Sectoral!$F$2:$F$20000,_Data_Sectoral!$A$2:$A$20000,"DE",_Data_Sectoral!$C$2:$C$20000,"data_centers",_Data_Sectoral!$D$2:$D$20000,"TOTAL",_Data_Sectoral!$E$2:$E$20000,2031) -> 38.589344 | J17: =SUMIFS(_Data_Sectoral!$F$2:$F$20000,_Data_Sectoral!$A$2:$A$20000,"DE",_Data_Sectoral!$C$2:$C$20000,"data_centers",_Data_Sectoral!$D$2:$D$20000,"TOTAL",_Data_Sectoral!$E$2:$E$20000,2032) -> 42.202804 | K17: =SUMIFS(_Data_Sectoral!$F$2:$F$20000,_Data_Sectoral!$A$2:$A$20000,"DE",_Data_Sectoral!$C$2:$C$20000,"data_centers",_Data_Sectoral!$D$2:$D$20000,"TOTAL",_Data_Sectoral!$E$2:$E$20000,2033) -> 45.802842 | L17: =SUMIFS(_Data_Sectoral!$F$2:$F$20000,_Data_Sectoral!$A$2:$A$20000,"DE",_Data_Sectoral!$C$2:$C$20000,"data_centers",_Data_Sectoral!$D$2:$D$20000,"TOTAL",_Data_Sectoral!$E$2:$E$20000,2034) -> 49.294674 | M17: =SUMIFS(_Data_Sectoral!$F$2:$F$20000,_Data_Sectoral!$A$2:$A$20000,"DE",_Data_Sectoral!$C$2:$C$20000,"data_centers",_Data_Sectoral!$D$2:$D$20000,"TOTAL",_Data_Sectoral!$E$2:$E$20000,2035) -> 52.576489 | N17: =SUMIFS(_Data_Sectoral!$F$2:$F$20000,_Data_Sectoral!$A$2:$A$20000,"DE",_Data_Sectoral!$C$2:$C$20000,"data_centers",_Data_Sectoral!$D$2:$D$20000,"TOTAL",_Data_Sectoral!$E$2:$E$20000,2036) -> 55.543886 | O17: =SUMIFS(_Data_Sectoral!$F$2:$F$20000,_Data_Sectoral!$A$2:$A$20000,"DE",_Data_Sectoral!$C$2:$C$20000,"data_centers",_Data_Sectoral!$D$2:$D$20000,"TOTAL",_Data_Sectoral!$E$2:$E$20000,2037) -> 58.095007 | P17: =SUMIFS(_Data_Sectoral!$F$2:$F$20000,_Data_Sectoral!$A$2:$A$20000,"DE",_Data_Sectoral!$C$2:$C$20000,"data_centers",_Data_Sectoral!$D$2:$D$20000,"TOTAL",_Data_Sectoral!$E$2:$E$20000,2038) -> 60.136045 | Q17: =SUMIFS(_Data_Sectoral!$F$2:$F$20000,_Data_Sectoral!$A$2:$A$20000,"DE",_Data_Sectoral!$C$2:$C$20000,"data_centers",_Data_Sectoral!$D$2:$D$20000,"TOTAL",_Data_Sectoral!$E$2:$E$20000,2039) -> 61.586742 | R17: =SUMIFS(_Data_Sectoral!$F$2:$F$20000,_Data_Sectoral!$A$2:$A$20000,"DE",_Data_Sectoral!$C$2:$C$20000,"data_centers",_Data_Sectoral!$D$2:$D$20000,"TOTAL",_Data_Sectoral!$E$2:$E$20000,2040) -> 62.385448
A18: Hydrogen | B18: =SUMIFS(_Data_Sectoral!$F$2:$F$20000,_Data_Sectoral!$A$2:$A$20000,"DE",_Data_Sectoral!$C$2:$C$20000,"hydrogen",_Data_Sectoral!$D$2:$D$20000,"TOTAL",_Data_Sectoral!$E$2:$E$20000,2024) -> 0.33 | C18: =SUMIFS(_Data_Sectoral!$F$2:$F$20000,_Data_Sectoral!$A$2:$A$20000,"DE",_Data_Sectoral!$C$2:$C$20000,"hydrogen",_Data_Sectoral!$D$2:$D$20000,"TOTAL",_Data_Sectoral!$E$2:$E$20000,2025) -> 0.51 | D18: =SUMIFS(_Data_Sectoral!$F$2:$F$20000,_Data_Sectoral!$A$2:$A$20000,"DE",_Data_Sectoral!$C$2:$C$20000,"hydrogen",_Data_Sectoral!$D$2:$D$20000,"TOTAL",_Data_Sectoral!$E$2:$E$20000,2026) -> 3.435668 | E18: =SUMIFS(_Data_Sectoral!$F$2:$F$20000,_Data_Sectoral!$A$2:$A$20000,"DE",_Data_Sectoral!$C$2:$C$20000,"hydrogen",_Data_Sectoral!$D$2:$D$20000,"TOTAL",_Data_Sectoral!$E$2:$E$20000,2027) -> 6.361337 | F18: =SUMIFS(_Data_Sectoral!$F$2:$F$20000,_Data_Sectoral!$A$2:$A$20000,"DE",_Data_Sectoral!$C$2:$C$20000,"hydrogen",_Data_Sectoral!$D$2:$D$20000,"TOTAL",_Data_Sectoral!$E$2:$E$20000,2028) -> 6.996787 | G18: =SUMIFS(_Data_Sectoral!$F$2:$F$20000,_Data_Sectoral!$A$2:$A$20000,"DE",_Data_Sectoral!$C$2:$C$20000,"hydrogen",_Data_Sectoral!$D$2:$D$20000,"TOTAL",_Data_Sectoral!$E$2:$E$20000,2029) -> 7.447752 | H18: =SUMIFS(_Data_Sectoral!$F$2:$F$20000,_Data_Sectoral!$A$2:$A$20000,"DE",_Data_Sectoral!$C$2:$C$20000,"hydrogen",_Data_Sectoral!$D$2:$D$20000,"TOTAL",_Data_Sectoral!$E$2:$E$20000,2030) -> 5.7159 | I18: =SUMIFS(_Data_Sectoral!$F$2:$F$20000,_Data_Sectoral!$A$2:$A$20000,"DE",_Data_Sectoral!$C$2:$C$20000,"hydrogen",_Data_Sectoral!$D$2:$D$20000,"TOTAL",_Data_Sectoral!$E$2:$E$20000,2031) -> 6.606004 | J18: =SUMIFS(_Data_Sectoral!$F$2:$F$20000,_Data_Sectoral!$A$2:$A$20000,"DE",_Data_Sectoral!$C$2:$C$20000,"hydrogen",_Data_Sectoral!$D$2:$D$20000,"TOTAL",_Data_Sectoral!$E$2:$E$20000,2032) -> 7.549718 | K18: =SUMIFS(_Data_Sectoral!$F$2:$F$20000,_Data_Sectoral!$A$2:$A$20000,"DE",_Data_Sectoral!$C$2:$C$20000,"hydrogen",_Data_Sectoral!$D$2:$D$20000,"TOTAL",_Data_Sectoral!$E$2:$E$20000,2033) -> 8.596714 | L18: =SUMIFS(_Data_Sectoral!$F$2:$F$20000,_Data_Sectoral!$A$2:$A$20000,"DE",_Data_Sectoral!$C$2:$C$20000,"hydrogen",_Data_Sectoral!$D$2:$D$20000,"TOTAL",_Data_Sectoral!$E$2:$E$20000,2034) -> 9.628729 | M18: =SUMIFS(_Data_Sectoral!$F$2:$F$20000,_Data_Sectoral!$A$2:$A$20000,"DE",_Data_Sectoral!$C$2:$C$20000,"hydrogen",_Data_Sectoral!$D$2:$D$20000,"TOTAL",_Data_Sectoral!$E$2:$E$20000,2035) -> 10.6434 | N18: =SUMIFS(_Data_Sectoral!$F$2:$F$20000,_Data_Sectoral!$A$2:$A$20000,"DE",_Data_Sectoral!$C$2:$C$20000,"hydrogen",_Data_Sectoral!$D$2:$D$20000,"TOTAL",_Data_Sectoral!$E$2:$E$20000,2036) -> 11.638361 | O18: =SUMIFS(_Data_Sectoral!$F$2:$F$20000,_Data_Sectoral!$A$2:$A$20000,"DE",_Data_Sectoral!$C$2:$C$20000,"hydrogen",_Data_Sectoral!$D$2:$D$20000,"TOTAL",_Data_Sectoral!$E$2:$E$20000,2037) -> 12.260934 | P18: =SUMIFS(_Data_Sectoral!$F$2:$F$20000,_Data_Sectoral!$A$2:$A$20000,"DE",_Data_Sectoral!$C$2:$C$20000,"hydrogen",_Data_Sectoral!$D$2:$D$20000,"TOTAL",_Data_Sectoral!$E$2:$E$20000,2038) -> 12.864323 | Q18: =SUMIFS(_Data_Sectoral!$F$2:$F$20000,_Data_Sectoral!$A$2:$A$20000,"DE",_Data_Sectoral!$C$2:$C$20000,"hydrogen",_Data_Sectoral!$D$2:$D$20000,"TOTAL",_Data_Sectoral!$E$2:$E$20000,2039) -> 13.44695 | R18: =SUMIFS(_Data_Sectoral!$F$2:$F$20000,_Data_Sectoral!$A$2:$A$20000,"DE",_Data_Sectoral!$C$2:$C$20000,"hydrogen",_Data_Sectoral!$D$2:$D$20000,"TOTAL",_Data_Sectoral!$E$2:$E$20000,2040) -> 13.6656
A19: Total | B19: =SUM(B14:B18) -> 475.51159 | C19: =SUM(C14:C18) -> 482.10556 | D19: =SUM(D14:D18) -> 493.90662 | E19: =SUM(E14:E18) -> 509.00687 | F19: =SUM(F14:F18) -> 521.62797 | G19: =SUM(G14:G18) -> 535.47251 | H19: =SUM(H14:H18) -> 551.23656 | I19: =SUM(I14:I18) -> 568.166 | ... R19: =SUM(R14:R18) -> 712.89394
A21: France
A22: Sector | B22: 2024 | C22: 2025 | D22: 2026 | E22: 2027 | F22: 2028 | G22: 2029 | H22: 2030 | I22: 2031 | J22: 2032 | K22: 2033 | L22: 2034 | M22: 2035 | N22: 2036 | O22: 2037 | P22: 2038 | Q22: 2039 | R22: 2040
A23: Transport | B23: =SUMIFS(_Data_Sectoral!$F$2:$F$20000,_Data_Sectoral!$A$2:$A$20000,"FR",_Data_Sectoral!$C$2:$C$20000,"transport",_Data_Sectoral!$D$2:$D$20000,"TOTAL",_Data_Sectoral!$E$2:$E$20000,2024) -> 12.17534 | C23: =SUMIFS(_Data_Sectoral!$F$2:$F$20000,_Data_Sectoral!$A$2:$A$20000,"FR",_Data_Sectoral!$C$2:$C$20000,"transport",_Data_Sectoral!$D$2:$D$20000,"TOTAL",_Data_Sectoral!$E$2:$E$20000,2025) -> 13.473119 | D23: =SUMIFS(_Data_Sectoral!$F$2:$F$20000,_Data_Sectoral!$A$2:$A$20000,"FR",_Data_Sectoral!$C$2:$C$20000,"transport",_Data_Sectoral!$D$2:$D$20000,"TOTAL",_Data_Sectoral!$E$2:$E$20000,2026) -> 15.060602 | E23: =SUMIFS(_Data_Sectoral!$F$2:$F$20000,_Data_Sectoral!$A$2:$A$20000,"FR",_Data_Sectoral!$C$2:$C$20000,"transport",_Data_Sectoral!$D$2:$D$20000,"TOTAL",_Data_Sectoral!$E$2:$E$20000,2027) -> 17.153697 | F23: =SUMIFS(_Data_Sectoral!$F$2:$F$20000,_Data_Sectoral!$A$2:$A$20000,"FR",_Data_Sectoral!$C$2:$C$20000,"transport",_Data_Sectoral!$D$2:$D$20000,"TOTAL",_Data_Sectoral!$E$2:$E$20000,2028) -> 19.948087 | G23: =SUMIFS(_Data_Sectoral!$F$2:$F$20000,_Data_Sectoral!$A$2:$A$20000,"FR",_Data_Sectoral!$C$2:$C$20000,"transport",_Data_Sectoral!$D$2:$D$20000,"TOTAL",_Data_Sectoral!$E$2:$E$20000,2029) -> 23.295812 | H23: =SUMIFS(_Data_Sectoral!$F$2:$F$20000,_Data_Sectoral!$A$2:$A$20000,"FR",_Data_Sectoral!$C$2:$C$20000,"transport",_Data_Sectoral!$D$2:$D$20000,"TOTAL",_Data_Sectoral!$E$2:$E$20000,2030) -> 27.051031 | I23: =SUMIFS(_Data_Sectoral!$F$2:$F$20000,_Data_Sectoral!$A$2:$A$20000,"FR",_Data_Sectoral!$C$2:$C$20000,"transport",_Data_Sectoral!$D$2:$D$20000,"TOTAL",_Data_Sectoral!$E$2:$E$20000,2031) -> 30.959984 | J23: =SUMIFS(_Data_Sectoral!$F$2:$F$20000,_Data_Sectoral!$A$2:$A$20000,"FR",_Data_Sectoral!$C$2:$C$20000,"transport",_Data_Sectoral!$D$2:$D$20000,"TOTAL",_Data_Sectoral!$E$2:$E$20000,2032) -> 35.155382 | K23: =SUMIFS(_Data_Sectoral!$F$2:$F$20000,_Data_Sectoral!$A$2:$A$20000,"FR",_Data_Sectoral!$C$2:$C$20000,"transport",_Data_Sectoral!$D$2:$D$20000,"TOTAL",_Data_Sectoral!$E$2:$E$20000,2033) -> 39.526301 | L23: =SUMIFS(_Data_Sectoral!$F$2:$F$20000,_Data_Sectoral!$A$2:$A$20000,"FR",_Data_Sectoral!$C$2:$C$20000,"transport",_Data_Sectoral!$D$2:$D$20000,"TOTAL",_Data_Sectoral!$E$2:$E$20000,2034) -> 44.018019 | M23: =SUMIFS(_Data_Sectoral!$F$2:$F$20000,_Data_Sectoral!$A$2:$A$20000,"FR",_Data_Sectoral!$C$2:$C$20000,"transport",_Data_Sectoral!$D$2:$D$20000,"TOTAL",_Data_Sectoral!$E$2:$E$20000,2035) -> 48.645395 | N23: =SUMIFS(_Data_Sectoral!$F$2:$F$20000,_Data_Sectoral!$A$2:$A$20000,"FR",_Data_Sectoral!$C$2:$C$20000,"transport",_Data_Sectoral!$D$2:$D$20000,"TOTAL",_Data_Sectoral!$E$2:$E$20000,2036) -> 53.188091 | O23: =SUMIFS(_Data_Sectoral!$F$2:$F$20000,_Data_Sectoral!$A$2:$A$20000,"FR",_Data_Sectoral!$C$2:$C$20000,"transport",_Data_Sectoral!$D$2:$D$20000,"TOTAL",_Data_Sectoral!$E$2:$E$20000,2037) -> 57.642584 | P23: =SUMIFS(_Data_Sectoral!$F$2:$F$20000,_Data_Sectoral!$A$2:$A$20000,"FR",_Data_Sectoral!$C$2:$C$20000,"transport",_Data_Sectoral!$D$2:$D$20000,"TOTAL",_Data_Sectoral!$E$2:$E$20000,2038) -> 62.097551 | Q23: =SUMIFS(_Data_Sectoral!$F$2:$F$20000,_Data_Sectoral!$A$2:$A$20000,"FR",_Data_Sectoral!$C$2:$C$20000,"transport",_Data_Sectoral!$D$2:$D$20000,"TOTAL",_Data_Sectoral!$E$2:$E$20000,2039) -> 66.080216 | R23: =SUMIFS(_Data_Sectoral!$F$2:$F$20000,_Data_Sectoral!$A$2:$A$20000,"FR",_Data_Sectoral!$C$2:$C$20000,"transport",_Data_Sectoral!$D$2:$D$20000,"TOTAL",_Data_Sectoral!$E$2:$E$20000,2040) -> 70.772028
A24: Buildings | B24: =SUMIFS(_Data_Sectoral!$F$2:$F$20000,_Data_Sectoral!$A$2:$A$20000,"FR",_Data_Sectoral!$C$2:$C$20000,"buildings",_Data_Sectoral!$D$2:$D$20000,"TOTAL",_Data_Sectoral!$E$2:$E$20000,2024) -> 276.97627 | C24: =SUMIFS(_Data_Sectoral!$F$2:$F$20000,_Data_Sectoral!$A$2:$A$20000,"FR",_Data_Sectoral!$C$2:$C$20000,"buildings",_Data_Sectoral!$D$2:$D$20000,"TOTAL",_Data_Sectoral!$E$2:$E$20000,2025) -> 280.70993 | D24: =SUMIFS(_Data_Sectoral!$F$2:$F$20000,_Data_Sectoral!$A$2:$A$20000,"FR",_Data_Sectoral!$C$2:$C$20000,"buildings",_Data_Sectoral!$D$2:$D$20000,"TOTAL",_Data_Sectoral!$E$2:$E$20000,2026) -> 284.22413 | E24: =SUMIFS(_Data_Sectoral!$F$2:$F$20000,_Data_Sectoral!$A$2:$A$20000,"FR",_Data_Sectoral!$C$2:$C$20000,"buildings",_Data_Sectoral!$D$2:$D$20000,"TOTAL",_Data_Sectoral!$E$2:$E$20000,2027) -> 287.8078 | F24: =SUMIFS(_Data_Sectoral!$F$2:$F$20000,_Data_Sectoral!$A$2:$A$20000,"FR",_Data_Sectoral!$C$2:$C$20000,"buildings",_Data_Sectoral!$D$2:$D$20000,"TOTAL",_Data_Sectoral!$E$2:$E$20000,2028) -> 292.35488 | G24: =SUMIFS(_Data_Sectoral!$F$2:$F$20000,_Data_Sectoral!$A$2:$A$20000,"FR",_Data_Sectoral!$C$2:$C$20000,"buildings",_Data_Sectoral!$D$2:$D$20000,"TOTAL",_Data_Sectoral!$E$2:$E$20000,2029) -> 297.41695 | H24: =SUMIFS(_Data_Sectoral!$F$2:$F$20000,_Data_Sectoral!$A$2:$A$20000,"FR",_Data_Sectoral!$C$2:$C$20000,"buildings",_Data_Sectoral!$D$2:$D$20000,"TOTAL",_Data_Sectoral!$E$2:$E$20000,2030) -> 303.02508 | I24: =SUMIFS(_Data_Sectoral!$F$2:$F$20000,_Data_Sectoral!$A$2:$A$20000,"FR",_Data_Sectoral!$C$2:$C$20000,"buildings",_Data_Sectoral!$D$2:$D$20000,"TOTAL",_Data_Sectoral!$E$2:$E$20000,2031) -> 307.87237 | J24: =SUMIFS(_Data_Sectoral!$F$2:$F$20000,_Data_Sectoral!$A$2:$A$20000,"FR",_Data_Sectoral!$C$2:$C$20000,"buildings",_Data_Sectoral!$D$2:$D$20000,"TOTAL",_Data_Sectoral!$E$2:$E$20000,2032) -> 312.99231 | K24: =SUMIFS(_Data_Sectoral!$F$2:$F$20000,_Data_Sectoral!$A$2:$A$20000,"FR",_Data_Sectoral!$C$2:$C$20000,"buildings",_Data_Sectoral!$D$2:$D$20000,"TOTAL",_Data_Sectoral!$E$2:$E$20000,2033) -> 318.58564 | L24: =SUMIFS(_Data_Sectoral!$F$2:$F$20000,_Data_Sectoral!$A$2:$A$20000,"FR",_Data_Sectoral!$C$2:$C$20000,"buildings",_Data_Sectoral!$D$2:$D$20000,"TOTAL",_Data_Sectoral!$E$2:$E$20000,2034) -> 324.96665 | M24: =SUMIFS(_Data_Sectoral!$F$2:$F$20000,_Data_Sectoral!$A$2:$A$20000,"FR",_Data_Sectoral!$C$2:$C$20000,"buildings",_Data_Sectoral!$D$2:$D$20000,"TOTAL",_Data_Sectoral!$E$2:$E$20000,2035) -> 331.32475 | N24: =SUMIFS(_Data_Sectoral!$F$2:$F$20000,_Data_Sectoral!$A$2:$A$20000,"FR",_Data_Sectoral!$C$2:$C$20000,"buildings",_Data_Sectoral!$D$2:$D$20000,"TOTAL",_Data_Sectoral!$E$2:$E$20000,2036) -> 336.68283 | O24: =SUMIFS(_Data_Sectoral!$F$2:$F$20000,_Data_Sectoral!$A$2:$A$20000,"FR",_Data_Sectoral!$C$2:$C$20000,"buildings",_Data_Sectoral!$D$2:$D$20000,"TOTAL",_Data_Sectoral!$E$2:$E$20000,2037) -> 341.41163 | P24: =SUMIFS(_Data_Sectoral!$F$2:$F$20000,_Data_Sectoral!$A$2:$A$20000,"FR",_Data_Sectoral!$C$2:$C$20000,"buildings",_Data_Sectoral!$D$2:$D$20000,"TOTAL",_Data_Sectoral!$E$2:$E$20000,2038) -> 346.87019 | Q24: =SUMIFS(_Data_Sectoral!$F$2:$F$20000,_Data_Sectoral!$A$2:$A$20000,"FR",_Data_Sectoral!$C$2:$C$20000,"buildings",_Data_Sectoral!$D$2:$D$20000,"TOTAL",_Data_Sectoral!$E$2:$E$20000,2039) -> 352.75671 | R24: =SUMIFS(_Data_Sectoral!$F$2:$F$20000,_Data_Sectoral!$A$2:$A$20000,"FR",_Data_Sectoral!$C$2:$C$20000,"buildings",_Data_Sectoral!$D$2:$D$20000,"TOTAL",_Data_Sectoral!$E$2:$E$20000,2040) -> 357.92401
A25: Industry | B25: =SUMIFS(_Data_Sectoral!$F$2:$F$20000,_Data_Sectoral!$A$2:$A$20000,"FR",_Data_Sectoral!$C$2:$C$20000,"industry",_Data_Sectoral!$D$2:$D$20000,"TOTAL",_Data_Sectoral!$E$2:$E$20000,2024) -> 113.68786 | C25: =SUMIFS(_Data_Sectoral!$F$2:$F$20000,_Data_Sectoral!$A$2:$A$20000,"FR",_Data_Sectoral!$C$2:$C$20000,"industry",_Data_Sectoral!$D$2:$D$20000,"TOTAL",_Data_Sectoral!$E$2:$E$20000,2025) -> 113.7473 | D25: =SUMIFS(_Data_Sectoral!$F$2:$F$20000,_Data_Sectoral!$A$2:$A$20000,"FR",_Data_Sectoral!$C$2:$C$20000,"industry",_Data_Sectoral!$D$2:$D$20000,"TOTAL",_Data_Sectoral!$E$2:$E$20000,2026) -> 113.75378 | E25: =SUMIFS(_Data_Sectoral!$F$2:$F$20000,_Data_Sectoral!$A$2:$A$20000,"FR",_Data_Sectoral!$C$2:$C$20000,"industry",_Data_Sectoral!$D$2:$D$20000,"TOTAL",_Data_Sectoral!$E$2:$E$20000,2027) -> 113.54681 | F25: =SUMIFS(_Data_Sectoral!$F$2:$F$20000,_Data_Sectoral!$A$2:$A$20000,"FR",_Data_Sectoral!$C$2:$C$20000,"industry",_Data_Sectoral!$D$2:$D$20000,"TOTAL",_Data_Sectoral!$E$2:$E$20000,2028) -> 113.64781 | G25: =SUMIFS(_Data_Sectoral!$F$2:$F$20000,_Data_Sectoral!$A$2:$A$20000,"FR",_Data_Sectoral!$C$2:$C$20000,"industry",_Data_Sectoral!$D$2:$D$20000,"TOTAL",_Data_Sectoral!$E$2:$E$20000,2029) -> 113.56379 | H25: =SUMIFS(_Data_Sectoral!$F$2:$F$20000,_Data_Sectoral!$A$2:$A$20000,"FR",_Data_Sectoral!$C$2:$C$20000,"industry",_Data_Sectoral!$D$2:$D$20000,"TOTAL",_Data_Sectoral!$E$2:$E$20000,2030) -> 116.15258 | I25: =SUMIFS(_Data_Sectoral!$F$2:$F$20000,_Data_Sectoral!$A$2:$A$20000,"FR",_Data_Sectoral!$C$2:$C$20000,"industry",_Data_Sectoral!$D$2:$D$20000,"TOTAL",_Data_Sectoral!$E$2:$E$20000,2031) -> 117.54518 | J25: =SUMIFS(_Data_Sectoral!$F$2:$F$20000,_Data_Sectoral!$A$2:$A$20000,"FR",_Data_Sectoral!$C$2:$C$20000,"industry",_Data_Sectoral!$D$2:$D$20000,"TOTAL",_Data_Sectoral!$E$2:$E$20000,2032) -> 119.90797 | K25: =SUMIFS(_Data_Sectoral!$F$2:$F$20000,_Data_Sectoral!$A$2:$A$20000,"FR",_Data_Sectoral!$C$2:$C$20000,"industry",_Data_Sectoral!$D$2:$D$20000,"TOTAL",_Data_Sectoral!$E$2:$E$20000,2033) -> 122.01932 | L25: =SUMIFS(_Data_Sectoral!$F$2:$F$20000,_Data_Sectoral!$A$2:$A$20000,"FR",_Data_Sectoral!$C$2:$C$20000,"industry",_Data_Sectoral!$D$2:$D$20000,"TOTAL",_Data_Sectoral!$E$2:$E$20000,2034) -> 124.42645 | M25: =SUMIFS(_Data_Sectoral!$F$2:$F$20000,_Data_Sectoral!$A$2:$A$20000,"FR",_Data_Sectoral!$C$2:$C$20000,"industry",_Data_Sectoral!$D$2:$D$20000,"TOTAL",_Data_Sectoral!$E$2:$E$20000,2035) -> 126.87382 | N25: =SUMIFS(_Data_Sectoral!$F$2:$F$20000,_Data_Sectoral!$A$2:$A$20000,"FR",_Data_Sectoral!$C$2:$C$20000,"industry",_Data_Sectoral!$D$2:$D$20000,"TOTAL",_Data_Sectoral!$E$2:$E$20000,2036) -> 129.56643 | O25: =SUMIFS(_Data_Sectoral!$F$2:$F$20000,_Data_Sectoral!$A$2:$A$20000,"FR",_Data_Sectoral!$C$2:$C$20000,"industry",_Data_Sectoral!$D$2:$D$20000,"TOTAL",_Data_Sectoral!$E$2:$E$20000,2037) -> 132.46104 | P25: =SUMIFS(_Data_Sectoral!$F$2:$F$20000,_Data_Sectoral!$A$2:$A$20000,"FR",_Data_Sectoral!$C$2:$C$20000,"industry",_Data_Sectoral!$D$2:$D$20000,"TOTAL",_Data_Sectoral!$E$2:$E$20000,2038) -> 135.38043 | Q25: =SUMIFS(_Data_Sectoral!$F$2:$F$20000,_Data_Sectoral!$A$2:$A$20000,"FR",_Data_Sectoral!$C$2:$C$20000,"industry",_Data_Sectoral!$D$2:$D$20000,"TOTAL",_Data_Sectoral!$E$2:$E$20000,2039) -> 138.37094 | R25: =SUMIFS(_Data_Sectoral!$F$2:$F$20000,_Data_Sectoral!$A$2:$A$20000,"FR",_Data_Sectoral!$C$2:$C$20000,"industry",_Data_Sectoral!$D$2:$D$20000,"TOTAL",_Data_Sectoral!$E$2:$E$20000,2040) -> 141.53192
A26: Data Centers | B26: =SUMIFS(_Data_Sectoral!$F$2:$F$20000,_Data_Sectoral!$A$2:$A$20000,"FR",_Data_Sectoral!$C$2:$C$20000,"data_centers",_Data_Sectoral!$D$2:$D$20000,"TOTAL",_Data_Sectoral!$E$2:$E$20000,2024) -> 5.8254 | C26: =SUMIFS(_Data_Sectoral!$F$2:$F$20000,_Data_Sectoral!$A$2:$A$20000,"FR",_Data_Sectoral!$C$2:$C$20000,"data_centers",_Data_Sectoral!$D$2:$D$20000,"TOTAL",_Data_Sectoral!$E$2:$E$20000,2025) -> 6.1510947 | D26: =SUMIFS(_Data_Sectoral!$F$2:$F$20000,_Data_Sectoral!$A$2:$A$20000,"FR",_Data_Sectoral!$C$2:$C$20000,"data_centers",_Data_Sectoral!$D$2:$D$20000,"TOTAL",_Data_Sectoral!$E$2:$E$20000,2026) -> 6.4714197 | E26: =SUMIFS(_Data_Sectoral!$F$2:$F$20000,_Data_Sectoral!$A$2:$A$20000,"FR",_Data_Sectoral!$C$2:$C$20000,"data_centers",_Data_Sectoral!$D$2:$D$20000,"TOTAL",_Data_Sectoral!$E$2:$E$20000,2027) -> 7.4139144 | F26: =SUMIFS(_Data_Sectoral!$F$2:$F$20000,_Data_Sectoral!$A$2:$A$20000,"FR",_Data_Sectoral!$C$2:$C$20000,"data_centers",_Data_Sectoral!$D$2:$D$20000,"TOTAL",_Data_Sectoral!$E$2:$E$20000,2028) -> 8.6168844 | G26: =SUMIFS(_Data_Sectoral!$F$2:$F$20000,_Data_Sectoral!$A$2:$A$20000,"FR",_Data_Sectoral!$C$2:$C$20000,"data_centers",_Data_Sectoral!$D$2:$D$20000,"TOTAL",_Data_Sectoral!$E$2:$E$20000,2029) -> 9.8998517 | H26: =SUMIFS(_Data_Sectoral!$F$2:$F$20000,_Data_Sectoral!$A$2:$A$20000,"FR",_Data_Sectoral!$C$2:$C$20000,"data_centers",_Data_Sectoral!$D$2:$D$20000,"TOTAL",_Data_Sectoral!$E$2:$E$20000,2030) -> 11.123894 | I26: =SUMIFS(_Data_Sectoral!$F$2:$F$20000,_Data_Sectoral!$A$2:$A$20000,"FR",_Data_Sectoral!$C$2:$C$20000,"data_centers",_Data_Sectoral!$D$2:$D$20000,"TOTAL",_Data_Sectoral!$E$2:$E$20000,2031) -> 12.339837 | J26: =SUMIFS(_Data_Sectoral!$F$2:$F$20000,_Data_Sectoral!$A$2:$A$20000,"FR",_Data_Sectoral!$C$2:$C$20000,"data_centers",_Data_Sectoral!$D$2:$D$20000,"TOTAL",_Data_Sectoral!$E$2:$E$20000,2032) -> 13.80182 | K26: =SUMIFS(_Data_Sectoral!$F$2:$F$20000,_Data_Sectoral!$A$2:$A$20000,"FR",_Data_Sectoral!$C$2:$C$20000,"data_centers",_Data_Sectoral!$D$2:$D$20000,"TOTAL",_Data_Sectoral!$E$2:$E$20000,2033) -> 15.258372 | L26: =SUMIFS(_Data_Sectoral!$F$2:$F$20000,_Data_Sectoral!$A$2:$A$20000,"FR",_Data_Sectoral!$C$2:$C$20000,"data_centers",_Data_Sectoral!$D$2:$D$20000,"TOTAL",_Data_Sectoral!$E$2:$E$20000,2034) -> 16.671144 | M26: =SUMIFS(_Data_Sectoral!$F$2:$F$20000,_Data_Sectoral!$A$2:$A$20000,"FR",_Data_Sectoral!$C$2:$C$20000,"data_centers",_Data_Sectoral!$D$2:$D$20000,"TOTAL",_Data_Sectoral!$E$2:$E$20000,2035) -> 17.998945 | N26: =SUMIFS(_Data_Sectoral!$F$2:$F$20000,_Data_Sectoral!$A$2:$A$20000,"FR",_Data_Sectoral!$C$2:$C$20000,"data_centers",_Data_Sectoral!$D$2:$D$20000,"TOTAL",_Data_Sectoral!$E$2:$E$20000,2036) -> 19.199535 | O26: =SUMIFS(_Data_Sectoral!$F$2:$F$20000,_Data_Sectoral!$A$2:$A$20000,"FR",_Data_Sectoral!$C$2:$C$20000,"data_centers",_Data_Sectoral!$D$2:$D$20000,"TOTAL",_Data_Sectoral!$E$2:$E$20000,2037) -> 20.231702 | P26: =SUMIFS(_Data_Sectoral!$F$2:$F$20000,_Data_Sectoral!$A$2:$A$20000,"FR",_Data_Sectoral!$C$2:$C$20000,"data_centers",_Data_Sectoral!$D$2:$D$20000,"TOTAL",_Data_Sectoral!$E$2:$E$20000,2038) -> 21.057493 | Q26: =SUMIFS(_Data_Sectoral!$F$2:$F$20000,_Data_Sectoral!$A$2:$A$20000,"FR",_Data_Sectoral!$C$2:$C$20000,"data_centers",_Data_Sectoral!$D$2:$D$20000,"TOTAL",_Data_Sectoral!$E$2:$E$20000,2039) -> 21.644435 | R26: =SUMIFS(_Data_Sectoral!$F$2:$F$20000,_Data_Sectoral!$A$2:$A$20000,"FR",_Data_Sectoral!$C$2:$C$20000,"data_centers",_Data_Sectoral!$D$2:$D$20000,"TOTAL",_Data_Sectoral!$E$2:$E$20000,2040) -> 21.967587
A27: Hydrogen | B27: =SUMIFS(_Data_Sectoral!$F$2:$F$20000,_Data_Sectoral!$A$2:$A$20000,"FR",_Data_Sectoral!$C$2:$C$20000,"hydrogen",_Data_Sectoral!$D$2:$D$20000,"TOTAL",_Data_Sectoral!$E$2:$E$20000,2024) -> 0.06 | C27: =SUMIFS(_Data_Sectoral!$F$2:$F$20000,_Data_Sectoral!$A$2:$A$20000,"FR",_Data_Sectoral!$C$2:$C$20000,"hydrogen",_Data_Sectoral!$D$2:$D$20000,"TOTAL",_Data_Sectoral!$E$2:$E$20000,2025) -> 0.075 | D27: =SUMIFS(_Data_Sectoral!$F$2:$F$20000,_Data_Sectoral!$A$2:$A$20000,"FR",_Data_Sectoral!$C$2:$C$20000,"hydrogen",_Data_Sectoral!$D$2:$D$20000,"TOTAL",_Data_Sectoral!$E$2:$E$20000,2026) -> 0.946262 | E27: =SUMIFS(_Data_Sectoral!$F$2:$F$20000,_Data_Sectoral!$A$2:$A$20000,"FR",_Data_Sectoral!$C$2:$C$20000,"hydrogen",_Data_Sectoral!$D$2:$D$20000,"TOTAL",_Data_Sectoral!$E$2:$E$20000,2027) -> 1.817525 | F27: =SUMIFS(_Data_Sectoral!$F$2:$F$20000,_Data_Sectoral!$A$2:$A$20000,"FR",_Data_Sectoral!$C$2:$C$20000,"hydrogen",_Data_Sectoral!$D$2:$D$20000,"TOTAL",_Data_Sectoral!$E$2:$E$20000,2028) -> 2.623795 | G27: =SUMIFS(_Data_Sectoral!$F$2:$F$20000,_Data_Sectoral!$A$2:$A$20000,"FR",_Data_Sectoral!$C$2:$C$20000,"hydrogen",_Data_Sectoral!$D$2:$D$20000,"TOTAL",_Data_Sectoral!$E$2:$E$20000,2029) -> 3.689712 | H27: =SUMIFS(_Data_Sectoral!$F$2:$F$20000,_Data_Sectoral!$A$2:$A$20000,"FR",_Data_Sectoral!$C$2:$C$20000,"hydrogen",_Data_Sectoral!$D$2:$D$20000,"TOTAL",_Data_Sectoral!$E$2:$E$20000,2030) -> 3.8106 | I27: =SUMIFS(_Data_Sectoral!$F$2:$F$20000,_Data_Sectoral!$A$2:$A$20000,"FR",_Data_Sectoral!$C$2:$C$20000,"hydrogen",_Data_Sectoral!$D$2:$D$20000,"TOTAL",_Data_Sectoral!$E$2:$E$20000,2031) -> 4.49388 | J27: =SUMIFS(_Data_Sectoral!$F$2:$F$20000,_Data_Sectoral!$A$2:$A$20000,"FR",_Data_Sectoral!$C$2:$C$20000,"hydrogen",_Data_Sectoral!$D$2:$D$20000,"TOTAL",_Data_Sectoral!$E$2:$E$20000,2032) -> 5.24286 | K27: =SUMIFS(_Data_Sectoral!$F$2:$F$20000,_Data_Sectoral!$A$2:$A$20000,"FR",_Data_Sectoral!$C$2:$C$20000,"hydrogen",_Data_Sectoral!$D$2:$D$20000,"TOTAL",_Data_Sectoral!$E$2:$E$20000,2033) -> 6.09696 | L27: =SUMIFS(_Data_Sectoral!$F$2:$F$20000,_Data_Sectoral!$A$2:$A$20000,"FR",_Data_Sectoral!$C$2:$C$20000,"hydrogen",_Data_Sectoral!$D$2:$D$20000,"TOTAL",_Data_Sectoral!$E$2:$E$20000,2034) -> 6.97734 | M27: =SUMIFS(_Data_Sectoral!$F$2:$F$20000,_Data_Sectoral!$A$2:$A$20000,"FR",_Data_Sectoral!$C$2:$C$20000,"hydrogen",_Data_Sectoral!$D$2:$D$20000,"TOTAL",_Data_Sectoral!$E$2:$E$20000,2035) -> 7.884 | N27: =SUMIFS(_Data_Sectoral!$F$2:$F$20000,_Data_Sectoral!$A$2:$A$20000,"FR",_Data_Sectoral!$C$2:$C$20000,"hydrogen",_Data_Sectoral!$D$2:$D$20000,"TOTAL",_Data_Sectoral!$E$2:$E$20000,2036) -> 8.81694 | O27: =SUMIFS(_Data_Sectoral!$F$2:$F$20000,_Data_Sectoral!$A$2:$A$20000,"FR",_Data_Sectoral!$C$2:$C$20000,"hydrogen",_Data_Sectoral!$D$2:$D$20000,"TOTAL",_Data_Sectoral!$E$2:$E$20000,2037) -> 9.5046 | P27: =SUMIFS(_Data_Sectoral!$F$2:$F$20000,_Data_Sectoral!$A$2:$A$20000,"FR",_Data_Sectoral!$C$2:$C$20000,"hydrogen",_Data_Sectoral!$D$2:$D$20000,"TOTAL",_Data_Sectoral!$E$2:$E$20000,2038) -> 10.20978 | Q27: =SUMIFS(_Data_Sectoral!$F$2:$F$20000,_Data_Sectoral!$A$2:$A$20000,"FR",_Data_Sectoral!$C$2:$C$20000,"hydrogen",_Data_Sectoral!$D$2:$D$20000,"TOTAL",_Data_Sectoral!$E$2:$E$20000,2039) -> 10.93248 | R27: =SUMIFS(_Data_Sectoral!$F$2:$F$20000,_Data_Sectoral!$A$2:$A$20000,"FR",_Data_Sectoral!$C$2:$C$20000,"hydrogen",_Data_Sectoral!$D$2:$D$20000,"TOTAL",_Data_Sectoral!$E$2:$E$20000,2040) -> 11.388
A28: Total | B28: =SUM(B23:B27) -> 408.72487 | C28: =SUM(C23:C27) -> 414.15645 | D28: =SUM(D23:D27) -> 420.45619 | E28: =SUM(E23:E27) -> 427.73974 | F28: =SUM(F23:F27) -> 437.19146 | G28: =SUM(G23:G27) -> 447.86612 | H28: =SUM(H23:H27) -> 461.16318 | I28: =SUM(I23:I27) -> 473.21125 | ... R28: =SUM(R23:R27) -> 603.58354
A30: Italy
A31: Sector | B31: 2024 | C31: 2025 | D31: 2026 | E31: 2027 | F31: 2028 | G31: 2029 | H31: 2030 | I31: 2031 | J31: 2032 | K31: 2033 | L31: 2034 | M31: 2035 | N31: 2036 | O31: 2037 | P31: 2038 | Q31: 2039 | R31: 2040
A32: Transport | B32: =SUMIFS(_Data_Sectoral!$F$2:$F$20000,_Data_Sectoral!$A$2:$A$20000,"IT",_Data_Sectoral!$C$2:$C$20000,"transport",_Data_Sectoral!$D$2:$D$20000,"TOTAL",_Data_Sectoral!$E$2:$E$20000,2024) -> 6.9918554 | C32: =SUMIFS(_Data_Sectoral!$F$2:$F$20000,_Data_Sectoral!$A$2:$A$20000,"IT",_Data_Sectoral!$C$2:$C$20000,"transport",_Data_Sectoral!$D$2:$D$20000,"TOTAL",_Data_Sectoral!$E$2:$E$20000,2025) -> 7.756669 | D32: =SUMIFS(_Data_Sectoral!$F$2:$F$20000,_Data_Sectoral!$A$2:$A$20000,"IT",_Data_Sectoral!$C$2:$C$20000,"transport",_Data_Sectoral!$D$2:$D$20000,"TOTAL",_Data_Sectoral!$E$2:$E$20000,2026) -> 8.7172499 | E32: =SUMIFS(_Data_Sectoral!$F$2:$F$20000,_Data_Sectoral!$A$2:$A$20000,"IT",_Data_Sectoral!$C$2:$C$20000,"transport",_Data_Sectoral!$D$2:$D$20000,"TOTAL",_Data_Sectoral!$E$2:$E$20000,2027) -> 10.069928 | F32: =SUMIFS(_Data_Sectoral!$F$2:$F$20000,_Data_Sectoral!$A$2:$A$20000,"IT",_Data_Sectoral!$C$2:$C$20000,"transport",_Data_Sectoral!$D$2:$D$20000,"TOTAL",_Data_Sectoral!$E$2:$E$20000,2028) -> 11.784853 | G32: =SUMIFS(_Data_Sectoral!$F$2:$F$20000,_Data_Sectoral!$A$2:$A$20000,"IT",_Data_Sectoral!$C$2:$C$20000,"transport",_Data_Sectoral!$D$2:$D$20000,"TOTAL",_Data_Sectoral!$E$2:$E$20000,2029) -> 13.815043 | H32: =SUMIFS(_Data_Sectoral!$F$2:$F$20000,_Data_Sectoral!$A$2:$A$20000,"IT",_Data_Sectoral!$C$2:$C$20000,"transport",_Data_Sectoral!$D$2:$D$20000,"TOTAL",_Data_Sectoral!$E$2:$E$20000,2030) -> 16.373009 | I32: =SUMIFS(_Data_Sectoral!$F$2:$F$20000,_Data_Sectoral!$A$2:$A$20000,"IT",_Data_Sectoral!$C$2:$C$20000,"transport",_Data_Sectoral!$D$2:$D$20000,"TOTAL",_Data_Sectoral!$E$2:$E$20000,2031) -> 19.118957 | J32: =SUMIFS(_Data_Sectoral!$F$2:$F$20000,_Data_Sectoral!$A$2:$A$20000,"IT",_Data_Sectoral!$C$2:$C$20000,"transport",_Data_Sectoral!$D$2:$D$20000,"TOTAL",_Data_Sectoral!$E$2:$E$20000,2032) -> 22.221643 | K32: =SUMIFS(_Data_Sectoral!$F$2:$F$20000,_Data_Sectoral!$A$2:$A$20000,"IT",_Data_Sectoral!$C$2:$C$20000,"transport",_Data_Sectoral!$D$2:$D$20000,"TOTAL",_Data_Sectoral!$E$2:$E$20000,2033) -> 25.669789 | L32: =SUMIFS(_Data_Sectoral!$F$2:$F$20000,_Data_Sectoral!$A$2:$A$20000,"IT",_Data_Sectoral!$C$2:$C$20000,"transport",_Data_Sectoral!$D$2:$D$20000,"TOTAL",_Data_Sectoral!$E$2:$E$20000,2034) -> 29.289093 | M32: =SUMIFS(_Data_Sectoral!$F$2:$F$20000,_Data_Sectoral!$A$2:$A$20000,"IT",_Data_Sectoral!$C$2:$C$20000,"transport",_Data_Sectoral!$D$2:$D$20000,"TOTAL",_Data_Sectoral!$E$2:$E$20000,2035) -> 33.026749 | N32: =SUMIFS(_Data_Sectoral!$F$2:$F$20000,_Data_Sectoral!$A$2:$A$20000,"IT",_Data_Sectoral!$C$2:$C$20000,"transport",_Data_Sectoral!$D$2:$D$20000,"TOTAL",_Data_Sectoral!$E$2:$E$20000,2036) -> 36.694065 | O32: =SUMIFS(_Data_Sectoral!$F$2:$F$20000,_Data_Sectoral!$A$2:$A$20000,"IT",_Data_Sectoral!$C$2:$C$20000,"transport",_Data_Sectoral!$D$2:$D$20000,"TOTAL",_Data_Sectoral!$E$2:$E$20000,2037) -> 40.254658 | P32: =SUMIFS(_Data_Sectoral!$F$2:$F$20000,_Data_Sectoral!$A$2:$A$20000,"IT",_Data_Sectoral!$C$2:$C$20000,"transport",_Data_Sectoral!$D$2:$D$20000,"TOTAL",_Data_Sectoral!$E$2:$E$20000,2038) -> 43.832381 | Q32: =SUMIFS(_Data_Sectoral!$F$2:$F$20000,_Data_Sectoral!$A$2:$A$20000,"IT",_Data_Sectoral!$C$2:$C$20000,"transport",_Data_Sectoral!$D$2:$D$20000,"TOTAL",_Data_Sectoral!$E$2:$E$20000,2039) -> 47.436794 | R32: =SUMIFS(_Data_Sectoral!$F$2:$F$20000,_Data_Sectoral!$A$2:$A$20000,"IT",_Data_Sectoral!$C$2:$C$20000,"transport",_Data_Sectoral!$D$2:$D$20000,"TOTAL",_Data_Sectoral!$E$2:$E$20000,2040) -> 51.076017
A33: Buildings | B33: =SUMIFS(_Data_Sectoral!$F$2:$F$20000,_Data_Sectoral!$A$2:$A$20000,"IT",_Data_Sectoral!$C$2:$C$20000,"buildings",_Data_Sectoral!$D$2:$D$20000,"TOTAL",_Data_Sectoral!$E$2:$E$20000,2024) -> 161.57879 | C33: =SUMIFS(_Data_Sectoral!$F$2:$F$20000,_Data_Sectoral!$A$2:$A$20000,"IT",_Data_Sectoral!$C$2:$C$20000,"buildings",_Data_Sectoral!$D$2:$D$20000,"TOTAL",_Data_Sectoral!$E$2:$E$20000,2025) -> 165.59265 | D33: =SUMIFS(_Data_Sectoral!$F$2:$F$20000,_Data_Sectoral!$A$2:$A$20000,"IT",_Data_Sectoral!$C$2:$C$20000,"buildings",_Data_Sectoral!$D$2:$D$20000,"TOTAL",_Data_Sectoral!$E$2:$E$20000,2026) -> 169.45082 | E33: =SUMIFS(_Data_Sectoral!$F$2:$F$20000,_Data_Sectoral!$A$2:$A$20000,"IT",_Data_Sectoral!$C$2:$C$20000,"buildings",_Data_Sectoral!$D$2:$D$20000,"TOTAL",_Data_Sectoral!$E$2:$E$20000,2027) -> 173.15061 | F33: =SUMIFS(_Data_Sectoral!$F$2:$F$20000,_Data_Sectoral!$A$2:$A$20000,"IT",_Data_Sectoral!$C$2:$C$20000,"buildings",_Data_Sectoral!$D$2:$D$20000,"TOTAL",_Data_Sectoral!$E$2:$E$20000,2028) -> 178.27475 | G33: =SUMIFS(_Data_Sectoral!$F$2:$F$20000,_Data_Sectoral!$A$2:$A$20000,"IT",_Data_Sectoral!$C$2:$C$20000,"buildings",_Data_Sectoral!$D$2:$D$20000,"TOTAL",_Data_Sectoral!$E$2:$E$20000,2029) -> 183.86682 | H33: =SUMIFS(_Data_Sectoral!$F$2:$F$20000,_Data_Sectoral!$A$2:$A$20000,"IT",_Data_Sectoral!$C$2:$C$20000,"buildings",_Data_Sectoral!$D$2:$D$20000,"TOTAL",_Data_Sectoral!$E$2:$E$20000,2030) -> 189.91731 | I33: =SUMIFS(_Data_Sectoral!$F$2:$F$20000,_Data_Sectoral!$A$2:$A$20000,"IT",_Data_Sectoral!$C$2:$C$20000,"buildings",_Data_Sectoral!$D$2:$D$20000,"TOTAL",_Data_Sectoral!$E$2:$E$20000,2031) -> 189.21479 | J33: =SUMIFS(_Data_Sectoral!$F$2:$F$20000,_Data_Sectoral!$A$2:$A$20000,"IT",_Data_Sectoral!$C$2:$C$20000,"buildings",_Data_Sectoral!$D$2:$D$20000,"TOTAL",_Data_Sectoral!$E$2:$E$20000,2032) -> 190.09259 | K33: =SUMIFS(_Data_Sectoral!$F$2:$F$20000,_Data_Sectoral!$A$2:$A$20000,"IT",_Data_Sectoral!$C$2:$C$20000,"buildings",_Data_Sectoral!$D$2:$D$20000,"TOTAL",_Data_Sectoral!$E$2:$E$20000,2033) -> 191.567 | L33: =SUMIFS(_Data_Sectoral!$F$2:$F$20000,_Data_Sectoral!$A$2:$A$20000,"IT",_Data_Sectoral!$C$2:$C$20000,"buildings",_Data_Sectoral!$D$2:$D$20000,"TOTAL",_Data_Sectoral!$E$2:$E$20000,2034) -> 194.06731 | M33: =SUMIFS(_Data_Sectoral!$F$2:$F$20000,_Data_Sectoral!$A$2:$A$20000,"IT",_Data_Sectoral!$C$2:$C$20000,"buildings",_Data_Sectoral!$D$2:$D$20000,"TOTAL",_Data_Sectoral!$E$2:$E$20000,2035) -> 196.43547 | N33: =SUMIFS(_Data_Sectoral!$F$2:$F$20000,_Data_Sectoral!$A$2:$A$20000,"IT",_Data_Sectoral!$C$2:$C$20000,"buildings",_Data_Sectoral!$D$2:$D$20000,"TOTAL",_Data_Sectoral!$E$2:$E$20000,2036) -> 198.18028 | O33: =SUMIFS(_Data_Sectoral!$F$2:$F$20000,_Data_Sectoral!$A$2:$A$20000,"IT",_Data_Sectoral!$C$2:$C$20000,"buildings",_Data_Sectoral!$D$2:$D$20000,"TOTAL",_Data_Sectoral!$E$2:$E$20000,2037) -> 197.21805 | P33: =SUMIFS(_Data_Sectoral!$F$2:$F$20000,_Data_Sectoral!$A$2:$A$20000,"IT",_Data_Sectoral!$C$2:$C$20000,"buildings",_Data_Sectoral!$D$2:$D$20000,"TOTAL",_Data_Sectoral!$E$2:$E$20000,2038) -> 197.45676 | Q33: =SUMIFS(_Data_Sectoral!$F$2:$F$20000,_Data_Sectoral!$A$2:$A$20000,"IT",_Data_Sectoral!$C$2:$C$20000,"buildings",_Data_Sectoral!$D$2:$D$20000,"TOTAL",_Data_Sectoral!$E$2:$E$20000,2039) -> 198.78386 | R33: =SUMIFS(_Data_Sectoral!$F$2:$F$20000,_Data_Sectoral!$A$2:$A$20000,"IT",_Data_Sectoral!$C$2:$C$20000,"buildings",_Data_Sectoral!$D$2:$D$20000,"TOTAL",_Data_Sectoral!$E$2:$E$20000,2040) -> 199.95515
A34: Industry | B34: =SUMIFS(_Data_Sectoral!$F$2:$F$20000,_Data_Sectoral!$A$2:$A$20000,"IT",_Data_Sectoral!$C$2:$C$20000,"industry",_Data_Sectoral!$D$2:$D$20000,"TOTAL",_Data_Sectoral!$E$2:$E$20000,2024) -> 126.41462 | C34: =SUMIFS(_Data_Sectoral!$F$2:$F$20000,_Data_Sectoral!$A$2:$A$20000,"IT",_Data_Sectoral!$C$2:$C$20000,"industry",_Data_Sectoral!$D$2:$D$20000,"TOTAL",_Data_Sectoral!$E$2:$E$20000,2025) -> 125.69363 | D34: =SUMIFS(_Data_Sectoral!$F$2:$F$20000,_Data_Sectoral!$A$2:$A$20000,"IT",_Data_Sectoral!$C$2:$C$20000,"industry",_Data_Sectoral!$D$2:$D$20000,"TOTAL",_Data_Sectoral!$E$2:$E$20000,2026) -> 125.15339 | E34: =SUMIFS(_Data_Sectoral!$F$2:$F$20000,_Data_Sectoral!$A$2:$A$20000,"IT",_Data_Sectoral!$C$2:$C$20000,"industry",_Data_Sectoral!$D$2:$D$20000,"TOTAL",_Data_Sectoral!$E$2:$E$20000,2027) -> 124.01604 | F34: =SUMIFS(_Data_Sectoral!$F$2:$F$20000,_Data_Sectoral!$A$2:$A$20000,"IT",_Data_Sectoral!$C$2:$C$20000,"industry",_Data_Sectoral!$D$2:$D$20000,"TOTAL",_Data_Sectoral!$E$2:$E$20000,2028) -> 123.34984 | G34: =SUMIFS(_Data_Sectoral!$F$2:$F$20000,_Data_Sectoral!$A$2:$A$20000,"IT",_Data_Sectoral!$C$2:$C$20000,"industry",_Data_Sectoral!$D$2:$D$20000,"TOTAL",_Data_Sectoral!$E$2:$E$20000,2029) -> 121.87812 | H34: =SUMIFS(_Data_Sectoral!$F$2:$F$20000,_Data_Sectoral!$A$2:$A$20000,"IT",_Data_Sectoral!$C$2:$C$20000,"industry",_Data_Sectoral!$D$2:$D$20000,"TOTAL",_Data_Sectoral!$E$2:$E$20000,2030) -> 120.56294 | I34: =SUMIFS(_Data_Sectoral!$F$2:$F$20000,_Data_Sectoral!$A$2:$A$20000,"IT",_Data_Sectoral!$C$2:$C$20000,"industry",_Data_Sectoral!$D$2:$D$20000,"TOTAL",_Data_Sectoral!$E$2:$E$20000,2031) -> 119.4092 | J34: =SUMIFS(_Data_Sectoral!$F$2:$F$20000,_Data_Sectoral!$A$2:$A$20000,"IT",_Data_Sectoral!$C$2:$C$20000,"industry",_Data_Sectoral!$D$2:$D$20000,"TOTAL",_Data_Sectoral!$E$2:$E$20000,2032) -> 119.50029 | K34: =SUMIFS(_Data_Sectoral!$F$2:$F$20000,_Data_Sectoral!$A$2:$A$20000,"IT",_Data_Sectoral!$C$2:$C$20000,"industry",_Data_Sectoral!$D$2:$D$20000,"TOTAL",_Data_Sectoral!$E$2:$E$20000,2033) -> 120.05171 | L34: =SUMIFS(_Data_Sectoral!$F$2:$F$20000,_Data_Sectoral!$A$2:$A$20000,"IT",_Data_Sectoral!$C$2:$C$20000,"industry",_Data_Sectoral!$D$2:$D$20000,"TOTAL",_Data_Sectoral!$E$2:$E$20000,2034) -> 121.12435 | M34: =SUMIFS(_Data_Sectoral!$F$2:$F$20000,_Data_Sectoral!$A$2:$A$20000,"IT",_Data_Sectoral!$C$2:$C$20000,"industry",_Data_Sectoral!$D$2:$D$20000,"TOTAL",_Data_Sectoral!$E$2:$E$20000,2035) -> 122.26552 | N34: =SUMIFS(_Data_Sectoral!$F$2:$F$20000,_Data_Sectoral!$A$2:$A$20000,"IT",_Data_Sectoral!$C$2:$C$20000,"industry",_Data_Sectoral!$D$2:$D$20000,"TOTAL",_Data_Sectoral!$E$2:$E$20000,2036) -> 123.31524 | O34: =SUMIFS(_Data_Sectoral!$F$2:$F$20000,_Data_Sectoral!$A$2:$A$20000,"IT",_Data_Sectoral!$C$2:$C$20000,"industry",_Data_Sectoral!$D$2:$D$20000,"TOTAL",_Data_Sectoral!$E$2:$E$20000,2037) -> 124.21124 | P34: =SUMIFS(_Data_Sectoral!$F$2:$F$20000,_Data_Sectoral!$A$2:$A$20000,"IT",_Data_Sectoral!$C$2:$C$20000,"industry",_Data_Sectoral!$D$2:$D$20000,"TOTAL",_Data_Sectoral!$E$2:$E$20000,2038) -> 125.27777 | Q34: =SUMIFS(_Data_Sectoral!$F$2:$F$20000,_Data_Sectoral!$A$2:$A$20000,"IT",_Data_Sectoral!$C$2:$C$20000,"industry",_Data_Sectoral!$D$2:$D$20000,"TOTAL",_Data_Sectoral!$E$2:$E$20000,2039) -> 126.43338 | R34: =SUMIFS(_Data_Sectoral!$F$2:$F$20000,_Data_Sectoral!$A$2:$A$20000,"IT",_Data_Sectoral!$C$2:$C$20000,"industry",_Data_Sectoral!$D$2:$D$20000,"TOTAL",_Data_Sectoral!$E$2:$E$20000,2040) -> 127.61561
A35: Data Centers | B35: =SUMIFS(_Data_Sectoral!$F$2:$F$20000,_Data_Sectoral!$A$2:$A$20000,"IT",_Data_Sectoral!$C$2:$C$20000,"data_centers",_Data_Sectoral!$D$2:$D$20000,"TOTAL",_Data_Sectoral!$E$2:$E$20000,2024) -> 2.199855 | C35: =SUMIFS(_Data_Sectoral!$F$2:$F$20000,_Data_Sectoral!$A$2:$A$20000,"IT",_Data_Sectoral!$C$2:$C$20000,"data_centers",_Data_Sectoral!$D$2:$D$20000,"TOTAL",_Data_Sectoral!$E$2:$E$20000,2025) -> 2.9586187 | D35: =SUMIFS(_Data_Sectoral!$F$2:$F$20000,_Data_Sectoral!$A$2:$A$20000,"IT",_Data_Sectoral!$C$2:$C$20000,"data_centers",_Data_Sectoral!$D$2:$D$20000,"TOTAL",_Data_Sectoral!$E$2:$E$20000,2026) -> 4.6581966 | E35: =SUMIFS(_Data_Sectoral!$F$2:$F$20000,_Data_Sectoral!$A$2:$A$20000,"IT",_Data_Sectoral!$C$2:$C$20000,"data_centers",_Data_Sectoral!$D$2:$D$20000,"TOTAL",_Data_Sectoral!$E$2:$E$20000,2027) -> 6.4495516 | F35: =SUMIFS(_Data_Sectoral!$F$2:$F$20000,_Data_Sectoral!$A$2:$A$20000,"IT",_Data_Sectoral!$C$2:$C$20000,"data_centers",_Data_Sectoral!$D$2:$D$20000,"TOTAL",_Data_Sectoral!$E$2:$E$20000,2028) -> 8.7758184 | G35: =SUMIFS(_Data_Sectoral!$F$2:$F$20000,_Data_Sectoral!$A$2:$A$20000,"IT",_Data_Sectoral!$C$2:$C$20000,"data_centers",_Data_Sectoral!$D$2:$D$20000,"TOTAL",_Data_Sectoral!$E$2:$E$20000,2029) -> 10.786399 | H35: =SUMIFS(_Data_Sectoral!$F$2:$F$20000,_Data_Sectoral!$A$2:$A$20000,"IT",_Data_Sectoral!$C$2:$C$20000,"data_centers",_Data_Sectoral!$D$2:$D$20000,"TOTAL",_Data_Sectoral!$E$2:$E$20000,2030) -> 12.357442 | I35: =SUMIFS(_Data_Sectoral!$F$2:$F$20000,_Data_Sectoral!$A$2:$A$20000,"IT",_Data_Sectoral!$C$2:$C$20000,"data_centers",_Data_Sectoral!$D$2:$D$20000,"TOTAL",_Data_Sectoral!$E$2:$E$20000,2031) -> 13.914587 | J35: =SUMIFS(_Data_Sectoral!$F$2:$F$20000,_Data_Sectoral!$A$2:$A$20000,"IT",_Data_Sectoral!$C$2:$C$20000,"data_centers",_Data_Sectoral!$D$2:$D$20000,"TOTAL",_Data_Sectoral!$E$2:$E$20000,2032) -> 15.56314 | K35: =SUMIFS(_Data_Sectoral!$F$2:$F$20000,_Data_Sectoral!$A$2:$A$20000,"IT",_Data_Sectoral!$C$2:$C$20000,"data_centers",_Data_Sectoral!$D$2:$D$20000,"TOTAL",_Data_Sectoral!$E$2:$E$20000,2033) -> 17.20557 | L35: =SUMIFS(_Data_Sectoral!$F$2:$F$20000,_Data_Sectoral!$A$2:$A$20000,"IT",_Data_Sectoral!$C$2:$C$20000,"data_centers",_Data_Sectoral!$D$2:$D$20000,"TOTAL",_Data_Sectoral!$E$2:$E$20000,2034) -> 18.798634 | M35: =SUMIFS(_Data_Sectoral!$F$2:$F$20000,_Data_Sectoral!$A$2:$A$20000,"IT",_Data_Sectoral!$C$2:$C$20000,"data_centers",_Data_Sectoral!$D$2:$D$20000,"TOTAL",_Data_Sectoral!$E$2:$E$20000,2035) -> 20.295883 | N35: =SUMIFS(_Data_Sectoral!$F$2:$F$20000,_Data_Sectoral!$A$2:$A$20000,"IT",_Data_Sectoral!$C$2:$C$20000,"data_centers",_Data_Sectoral!$D$2:$D$20000,"TOTAL",_Data_Sectoral!$E$2:$E$20000,2036) -> 21.649686 | O35: =SUMIFS(_Data_Sectoral!$F$2:$F$20000,_Data_Sectoral!$A$2:$A$20000,"IT",_Data_Sectoral!$C$2:$C$20000,"data_centers",_Data_Sectoral!$D$2:$D$20000,"TOTAL",_Data_Sectoral!$E$2:$E$20000,2037) -> 22.813573 | P35: =SUMIFS(_Data_Sectoral!$F$2:$F$20000,_Data_Sectoral!$A$2:$A$20000,"IT",_Data_Sectoral!$C$2:$C$20000,"data_centers",_Data_Sectoral!$D$2:$D$20000,"TOTAL",_Data_Sectoral!$E$2:$E$20000,2038) -> 23.744747 | Q35: =SUMIFS(_Data_Sectoral!$F$2:$F$20000,_Data_Sectoral!$A$2:$A$20000,"IT",_Data_Sectoral!$C$2:$C$20000,"data_centers",_Data_Sectoral!$D$2:$D$20000,"TOTAL",_Data_Sectoral!$E$2:$E$20000,2039) -> 24.406592 | R35: =SUMIFS(_Data_Sectoral!$F$2:$F$20000,_Data_Sectoral!$A$2:$A$20000,"IT",_Data_Sectoral!$C$2:$C$20000,"data_centers",_Data_Sectoral!$D$2:$D$20000,"TOTAL",_Data_Sectoral!$E$2:$E$20000,2040) -> 24.770983
